Workbook

Sheet Sheet1
A1: Activity Category | B1: Cost Code | C1: Section | D1: Activity | E1: Claude Start | F1: Claude Finish | G1: Start Date | H1: Finish Date | I1: Total Hrs | J1: 46194 | K1: 46201 | L1: 46208 | M1: 46215 | N1: 46222 | O1: 46229 | P1: 46236 | Q1: 46243 | R1: 46250 | S1: 46257 | T1: 46264 | U1: 46271 | V1: 46278 | W1: 46285 | X1: 46292 | Y1: 46299 | Z1: 46306 | AA1: 46313 | AB1: 46320 | AC1: 46327 | AD1: 46334 | AE1: 46341 | AF1: 46348 | AG1: 46355 | AH1: 46362 | AI1: 46369 | AJ1: 46376 | AK1: 46383 | AL1: 46390 | AM1: 46397 | AN1: 46404 | AO1: 46411 | AP1: 46418 | AQ1: 46425 | AR1: 46432 | AS1: 46439 | AT1: 46446 | AU1: 46453 | AV1: 46460 | AW1: 46467 | AX1: 46474 | AY1: 46481 | AZ1: 46488 | BA1: 46495 | BB1: 46502 | BC1: 46509 | BD1: 46516 | BE1: 46523 | BF1: 46530 | BG1: 46537 | BH1: 46544 | BI1: 46551 | BJ1: 46558 | BK1: 46565 | BL1: 46572 | BM1: 46579 | BN1: 46586 | BO1: 46593 | BP1: 46600 | BQ1: 46607 | BR1: 46614 | BS1: 46621 | BT1: 46628 | BU1: 46635 | BV1: 46642 | BW1: 46649 | BX1: 46656 | BY1: 46663 | BZ1: 46670 | CA1: 46677 | CB1: 46684 | CC1: 46691 | CD1: 46698 | CE1: 46705 | CF1: 46712 | CG1: 46719 | CH1: 46726 | CI1: 46733 | CJ1: 46740 | CK1: 46747 | CL1: 46754 | CM1: 46761 | CN1: 46768 | CO1: 46775 | CP1: 46782 | CQ1: 46789 | CR1: 46796 | CS1: 46803 | CT1: 46810 | CU1: 46817 | CV1: 46824 | CW1: 46831 | CX1: 46838 | CY1: 46845 | CZ1: 46852 | DA1: 46859 | DB1: 46866 | DC1: 46873 | DD1: 46880 | DE1: 46887 | DF1: 46894 | DG1: 46901 | DH1: 46908 | DI1: 46915 | DJ1: 46922 | DK1: 46929 | DL1: 46936 | DM1: 46943 | DN1: 46950 | DO1: 46957 | DP1: 46964 | DQ1: 46971 | DR1: 46978 | DS1: 46985 | DT1: 46992 | DU1: 46999 | DV1: 47006 | DW1: 47013 | DX1: 47020 | DY1: 47027 | DZ1: 47034 | EA1: 47041 | EB1: 47048 | EC1: 47055 | ED1: 47062 | EE1: 47069 | EF1: 47076 | EG1: 47083 | EH1: 47090 | EI1: 47097 | EJ1: 47104 | EK1: 47111 | EL1: 47118 | EM1: 47125 | EN1: 47132 | EO1: 47139 | EP1: 47146 | EQ1: 47153 | ER1: 47160 | ES1: 47167 | ET1: 47174 | EU1: 47181 | EV1: 47188 | EW1: 47195 | EX1: 47202 | EY1: 47209 | EZ1: 47216 | FA1: 47223 | FB1: 47230 | FC1: 47237 | FD1: 47244 | FE1: 47251 | FF1: 47258 | FG1: 47265 | FH1: 47272 | FI1: 47279 | FJ1: 47286 | FK1: 47293 | FL1: 47300 | FM1: 47307 | FN1: 47314 | FO1: 47321 | FP1: 47328 | FQ1: 47335 | FR1: 47342 | FS1: 47349 | FT1: 47356 | FU1: 47363 | FV1: 47370 | FW1: 47377 | FX1: 47384 | FY1: 47391 | FZ1: 47398 | GA1: 47405 | GB1: 47412 | GC1: 47419 | GD1: 47426 | GE1: 47433 | GF1: 47440 | GG1: 47447 | GH1: 47454 | GI1: 47461 | GJ1: 47468 | GK1: 47475 | GL1: 47482
I2: 0 | J2: =IF(Weights!$E2=0,0,$I2*Weights!J2/Weights!$E2) -> 0 | K2: =IF(Weights!$E2=0,0,$I2*Weights!K2/Weights!$E2) -> 0 | L2: =IF(Weights!$E2=0,0,$I2*Weights!L2/Weights!$E2) -> 0 | M2: =IF(Weights!$E2=0,0,$I2*Weights!M2/Weights!$E2) -> 0 | N2: =IF(Weights!$E2=0,0,$I2*Weights!N2/Weights!$E2) -> 0 | O2: =IF(Weights!$E2=0,0,$I2*Weights!O2/Weights!$E2) -> 0 | P2: =IF(Weights!$E2=0,0,$I2*Weights!P2/Weights!$E2) -> 0 | Q2: =IF(Weights!$E2=0,0,$I2*Weights!Q2/Weights!$E2) -> 0 | ... GL2: =IF(Weights!$E2=0,0,$I2*Weights!GL2/Weights!$E2) -> 0
I3: 0 | J3: =IF(Weights!$E3=0,0,$I3*Weights!J3/Weights!$E3) -> 0 | K3: =IF(Weights!$E3=0,0,$I3*Weights!K3/Weights!$E3) -> 0 | L3: =IF(Weights!$E3=0,0,$I3*Weights!L3/Weights!$E3) -> 0 | M3: =IF(Weights!$E3=0,0,$I3*Weights!M3/Weights!$E3) -> 0 | N3: =IF(Weights!$E3=0,0,$I3*Weights!N3/Weights!$E3) -> 0 | O3: =IF(Weights!$E3=0,0,$I3*Weights!O3/Weights!$E3) -> 0 | P3: =IF(Weights!$E3=0,0,$I3*Weights!P3/Weights!$E3) -> 0 | Q3: =IF(Weights!$E3=0,0,$I3*Weights!Q3/Weights!$E3) -> 0 | ... GL3: =IF(Weights!$E3=0,0,$I3*Weights!GL3/Weights!$E3) -> 0
A4: NP-WHC | B4: 0-4000-01 | C4: Civil | D4: 0-4000-01-Mobilization | E4: 46188 | F4: 46303 | G4: 46300 | H4: 46325 | I4: 200 | J4: =IF(Weights!$E4=0,0,$I4*Weights!J4/Weights!$E4) -> 0 | K4: =IF(Weights!$E4=0,0,$I4*Weights!K4/Weights!$E4) -> 0 | L4: =IF(Weights!$E4=0,0,$I4*Weights!L4/Weights!$E4) -> 0 | M4: =IF(Weights!$E4=0,0,$I4*Weights!M4/Weights!$E4) -> 0 | N4: =IF(Weights!$E4=0,0,$I4*Weights!N4/Weights!$E4) -> 0 | O4: =IF(Weights!$E4=0,0,$I4*Weights!O4/Weights!$E4) -> 0 | P4: =IF(Weights!$E4=0,0,$I4*Weights!P4/Weights!$E4) -> 0 | Q4: =IF(Weights!$E4=0,0,$I4*Weights!Q4/Weights!$E4) -> 0 | ... GL4: =IF(Weights!$E4=0,0,$I4*Weights!GL4/Weights!$E4) -> 0
A5: NP-WHC | B5: 0-4001-01 | C5: Civil | D5: 0-4001-01-DeMobilization | E5: 46637 | F5: 46637 | G5: 46637 | H5: 46637 | I5: 220 | J5: =IF(Weights!$E5=0,0,$I5*Weights!J5/Weights!$E5) -> 0 | K5: =IF(Weights!$E5=0,0,$I5*Weights!K5/Weights!$E5) -> 0 | L5: =IF(Weights!$E5=0,0,$I5*Weights!L5/Weights!$E5) -> 0 | M5: =IF(Weights!$E5=0,0,$I5*Weights!M5/Weights!$E5) -> 0 | N5: =IF(Weights!$E5=0,0,$I5*Weights!N5/Weights!$E5) -> 0 | O5: =IF(Weights!$E5=0,0,$I5*Weights!O5/Weights!$E5) -> 0 | P5: =IF(Weights!$E5=0,0,$I5*Weights!P5/Weights!$E5) -> 0 | Q5: =IF(Weights!$E5=0,0,$I5*Weights!Q5/Weights!$E5) -> 0 | ... GL5: =IF(Weights!$E5=0,0,$I5*Weights!GL5/Weights!$E5) -> 0
A6: NP-WHC | B6: 0-4004-01 | C6: PV | I6: 0 | J6: =IF(Weights!$E6=0,0,$I6*Weights!J6/Weights!$E6) -> 0 | K6: =IF(Weights!$E6=0,0,$I6*Weights!K6/Weights!$E6) -> 0 | L6: =IF(Weights!$E6=0,0,$I6*Weights!L6/Weights!$E6) -> 0 | M6: =IF(Weights!$E6=0,0,$I6*Weights!M6/Weights!$E6) -> 0 | N6: =IF(Weights!$E6=0,0,$I6*Weights!N6/Weights!$E6) -> 0 | O6: =IF(Weights!$E6=0,0,$I6*Weights!O6/Weights!$E6) -> 0 | P6: =IF(Weights!$E6=0,0,$I6*Weights!P6/Weights!$E6) -> 0 | Q6: =IF(Weights!$E6=0,0,$I6*Weights!Q6/Weights!$E6) -> 0 | ... GL6: =IF(Weights!$E6=0,0,$I6*Weights!GL6/Weights!$E6) -> 0
A7: NP-WHC | B7: 0-4004-05 | C7: PV | I7: 0 | J7: =IF(Weights!$E7=0,0,$I7*Weights!J7/Weights!$E7) -> 0 | K7: =IF(Weights!$E7=0,0,$I7*Weights!K7/Weights!$E7) -> 0 | L7: =IF(Weights!$E7=0,0,$I7*Weights!L7/Weights!$E7) -> 0 | M7: =IF(Weights!$E7=0,0,$I7*Weights!M7/Weights!$E7) -> 0 | N7: =IF(Weights!$E7=0,0,$I7*Weights!N7/Weights!$E7) -> 0 | O7: =IF(Weights!$E7=0,0,$I7*Weights!O7/Weights!$E7) -> 0 | P7: =IF(Weights!$E7=0,0,$I7*Weights!P7/Weights!$E7) -> 0 | Q7: =IF(Weights!$E7=0,0,$I7*Weights!Q7/Weights!$E7) -> 0 | ... GL7: =IF(Weights!$E7=0,0,$I7*Weights!GL7/Weights!$E7) -> 0
A8: NP-WHC | B8: 0-4004-06 | C8: PV | I8: 0 | J8: =IF(Weights!$E8=0,0,$I8*Weights!J8/Weights!$E8) -> 0 | K8: =IF(Weights!$E8=0,0,$I8*Weights!K8/Weights!$E8) -> 0 | L8: =IF(Weights!$E8=0,0,$I8*Weights!L8/Weights!$E8) -> 0 | M8: =IF(Weights!$E8=0,0,$I8*Weights!M8/Weights!$E8) -> 0 | N8: =IF(Weights!$E8=0,0,$I8*Weights!N8/Weights!$E8) -> 0 | O8: =IF(Weights!$E8=0,0,$I8*Weights!O8/Weights!$E8) -> 0 | P8: =IF(Weights!$E8=0,0,$I8*Weights!P8/Weights!$E8) -> 0 | Q8: =IF(Weights!$E8=0,0,$I8*Weights!Q8/Weights!$E8) -> 0 | ... GL8: =IF(Weights!$E8=0,0,$I8*Weights!GL8/Weights!$E8) -> 0
A9: NP-WHC | B9: 0-4004-07 | C9: PV | I9: 0 | J9: =IF(Weights!$E9=0,0,$I9*Weights!J9/Weights!$E9) -> 0 | K9: =IF(Weights!$E9=0,0,$I9*Weights!K9/Weights!$E9) -> 0 | L9: =IF(Weights!$E9=0,0,$I9*Weights!L9/Weights!$E9) -> 0 | M9: =IF(Weights!$E9=0,0,$I9*Weights!M9/Weights!$E9) -> 0 | N9: =IF(Weights!$E9=0,0,$I9*Weights!N9/Weights!$E9) -> 0 | O9: =IF(Weights!$E9=0,0,$I9*Weights!O9/Weights!$E9) -> 0 | P9: =IF(Weights!$E9=0,0,$I9*Weights!P9/Weights!$E9) -> 0 | Q9: =IF(Weights!$E9=0,0,$I9*Weights!Q9/Weights!$E9) -> 0 | ... GL9: =IF(Weights!$E9=0,0,$I9*Weights!GL9/Weights!$E9) -> 0
A10: NP-WHC | B10: 0-4004-08 | C10: PV | I10: 0 | J10: =IF(Weights!$E10=0,0,$I10*Weights!J10/Weights!$E10) -> 0 | K10: =IF(Weights!$E10=0,0,$I10*Weights!K10/Weights!$E10) -> 0 | L10: =IF(Weights!$E10=0,0,$I10*Weights!L10/Weights!$E10) -> 0 | M10: =IF(Weights!$E10=0,0,$I10*Weights!M10/Weights!$E10) -> 0 | N10: =IF(Weights!$E10=0,0,$I10*Weights!N10/Weights!$E10) -> 0 | O10: =IF(Weights!$E10=0,0,$I10*Weights!O10/Weights!$E10) -> 0 | P10: =IF(Weights!$E10=0,0,$I10*Weights!P10/Weights!$E10) -> 0 | Q10: =IF(Weights!$E10=0,0,$I10*Weights!Q10/Weights!$E10) -> 0 | ... GL10: =IF(Weights!$E10=0,0,$I10*Weights!GL10/Weights!$E10) -> 0
A11: NP-WHC | B11: 0-4004-10 | C11: PV | I11: 0 | J11: =IF(Weights!$E11=0,0,$I11*Weights!J11/Weights!$E11) -> 0 | K11: =IF(Weights!$E11=0,0,$I11*Weights!K11/Weights!$E11) -> 0 | L11: =IF(Weights!$E11=0,0,$I11*Weights!L11/Weights!$E11) -> 0 | M11: =IF(Weights!$E11=0,0,$I11*Weights!M11/Weights!$E11) -> 0 | N11: =IF(Weights!$E11=0,0,$I11*Weights!N11/Weights!$E11) -> 0 | O11: =IF(Weights!$E11=0,0,$I11*Weights!O11/Weights!$E11) -> 0 | P11: =IF(Weights!$E11=0,0,$I11*Weights!P11/Weights!$E11) -> 0 | Q11: =IF(Weights!$E11=0,0,$I11*Weights!Q11/Weights!$E11) -> 0 | ... GL11: =IF(Weights!$E11=0,0,$I11*Weights!GL11/Weights!$E11) -> 0
A12: NP-WHC | B12: 0-4004-11 | C12: PV | I12: 0 | J12: =IF(Weights!$E12=0,0,$I12*Weights!J12/Weights!$E12) -> 0 | K12: =IF(Weights!$E12=0,0,$I12*Weights!K12/Weights!$E12) -> 0 | L12: =IF(Weights!$E12=0,0,$I12*Weights!L12/Weights!$E12) -> 0 | M12: =IF(Weights!$E12=0,0,$I12*Weights!M12/Weights!$E12) -> 0 | N12: =IF(Weights!$E12=0,0,$I12*Weights!N12/Weights!$E12) -> 0 | O12: =IF(Weights!$E12=0,0,$I12*Weights!O12/Weights!$E12) -> 0 | P12: =IF(Weights!$E12=0,0,$I12*Weights!P12/Weights!$E12) -> 0 | Q12: =IF(Weights!$E12=0,0,$I12*Weights!Q12/Weights!$E12) -> 0 | ... GL12: =IF(Weights!$E12=0,0,$I12*Weights!GL12/Weights!$E12) -> 0
A13: NP-WHC | B13: 0-4004-15 | C13: Civil | I13: 0 | J13: =IF(Weights!$E13=0,0,$I13*Weights!J13/Weights!$E13) -> 0 | K13: =IF(Weights!$E13=0,0,$I13*Weights!K13/Weights!$E13) -> 0 | L13: =IF(Weights!$E13=0,0,$I13*Weights!L13/Weights!$E13) -> 0 | M13: =IF(Weights!$E13=0,0,$I13*Weights!M13/Weights!$E13) -> 0 | N13: =IF(Weights!$E13=0,0,$I13*Weights!N13/Weights!$E13) -> 0 | O13: =IF(Weights!$E13=0,0,$I13*Weights!O13/Weights!$E13) -> 0 | P13: =IF(Weights!$E13=0,0,$I13*Weights!P13/Weights!$E13) -> 0 | Q13: =IF(Weights!$E13=0,0,$I13*Weights!Q13/Weights!$E13) -> 0 | ... GL13: =IF(Weights!$E13=0,0,$I13*Weights!GL13/Weights!$E13) -> 0
A14: NP-WHC | B14: 0-4004-16 | C14: Civil | I14: 0 | J14: =IF(Weights!$E14=0,0,$I14*Weights!J14/Weights!$E14) -> 0 | K14: =IF(Weights!$E14=0,0,$I14*Weights!K14/Weights!$E14) -> 0 | L14: =IF(Weights!$E14=0,0,$I14*Weights!L14/Weights!$E14) -> 0 | M14: =IF(Weights!$E14=0,0,$I14*Weights!M14/Weights!$E14) -> 0 | N14: =IF(Weights!$E14=0,0,$I14*Weights!N14/Weights!$E14) -> 0 | O14: =IF(Weights!$E14=0,0,$I14*Weights!O14/Weights!$E14) -> 0 | P14: =IF(Weights!$E14=0,0,$I14*Weights!P14/Weights!$E14) -> 0 | Q14: =IF(Weights!$E14=0,0,$I14*Weights!Q14/Weights!$E14) -> 0 | ... GL14: =IF(Weights!$E14=0,0,$I14*Weights!GL14/Weights!$E14) -> 0
A15: NP-WHC | B15: 0-4004-17 | C15: Civil | I15: 0 | J15: =IF(Weights!$E15=0,0,$I15*Weights!J15/Weights!$E15) -> 0 | K15: =IF(Weights!$E15=0,0,$I15*Weights!K15/Weights!$E15) -> 0 | L15: =IF(Weights!$E15=0,0,$I15*Weights!L15/Weights!$E15) -> 0 | M15: =IF(Weights!$E15=0,0,$I15*Weights!M15/Weights!$E15) -> 0 | N15: =IF(Weights!$E15=0,0,$I15*Weights!N15/Weights!$E15) -> 0 | O15: =IF(Weights!$E15=0,0,$I15*Weights!O15/Weights!$E15) -> 0 | P15: =IF(Weights!$E15=0,0,$I15*Weights!P15/Weights!$E15) -> 0 | Q15: =IF(Weights!$E15=0,0,$I15*Weights!Q15/Weights!$E15) -> 0 | ... GL15: =IF(Weights!$E15=0,0,$I15*Weights!GL15/Weights!$E15) -> 0
A16: NP-WHC | B16: 0-4004-18 | C16: Civil | I16: 0 | J16: =IF(Weights!$E16=0,0,$I16*Weights!J16/Weights!$E16) -> 0 | K16: =IF(Weights!$E16=0,0,$I16*Weights!K16/Weights!$E16) -> 0 | L16: =IF(Weights!$E16=0,0,$I16*Weights!L16/Weights!$E16) -> 0 | M16: =IF(Weights!$E16=0,0,$I16*Weights!M16/Weights!$E16) -> 0 | N16: =IF(Weights!$E16=0,0,$I16*Weights!N16/Weights!$E16) -> 0 | O16: =IF(Weights!$E16=0,0,$I16*Weights!O16/Weights!$E16) -> 0 | P16: =IF(Weights!$E16=0,0,$I16*Weights!P16/Weights!$E16) -> 0 | Q16: =IF(Weights!$E16=0,0,$I16*Weights!Q16/Weights!$E16) -> 0 | ... GL16: =IF(Weights!$E16=0,0,$I16*Weights!GL16/Weights!$E16) -> 0
A17: NP-WHC | B17: 0-4005 | C17: PV | D17: 0-4005-FOE | E17: 46326 | F17: 46531 | G17: 46326 | H17: 46531 | I17: 22459 | J17: =IF(Weights!$E17=0,0,$I17*Weights!J17/Weights!$E17) -> 0 | K17: =IF(Weights!$E17=0,0,$I17*Weights!K17/Weights!$E17) -> 0 | L17: =IF(Weights!$E17=0,0,$I17*Weights!L17/Weights!$E17) -> 0 | M17: =IF(Weights!$E17=0,0,$I17*Weights!M17/Weights!$E17) -> 0 | N17: =IF(Weights!$E17=0,0,$I17*Weights!N17/Weights!$E17) -> 0 | O17: =IF(Weights!$E17=0,0,$I17*Weights!O17/Weights!$E17) -> 0 | P17: =IF(Weights!$E17=0,0,$I17*Weights!P17/Weights!$E17) -> 0 | Q17: =IF(Weights!$E17=0,0,$I17*Weights!Q17/Weights!$E17) -> 0 | ... GL17: =IF(Weights!$E17=0,0,$I17*Weights!GL17/Weights!$E17) -> 0
A18: NP-WHC | B18: 0-4005-01 | C18: Civil | D18: 0-4005-01-Civil FOE | E18: 46300 | F18: 46325 | G18: 46300 | H18: 46325 | I18: 5255 | J18: =IF(Weights!$E18=0,0,$I18*Weights!J18/Weights!$E18) -> 0 | K18: =IF(Weights!$E18=0,0,$I18*Weights!K18/Weights!$E18) -> 0 | L18: =IF(Weights!$E18=0,0,$I18*Weights!L18/Weights!$E18) -> 0 | M18: =IF(Weights!$E18=0,0,$I18*Weights!M18/Weights!$E18) -> 0 | N18: =IF(Weights!$E18=0,0,$I18*Weights!N18/Weights!$E18) -> 0 | O18: =IF(Weights!$E18=0,0,$I18*Weights!O18/Weights!$E18) -> 0 | P18: =IF(Weights!$E18=0,0,$I18*Weights!P18/Weights!$E18) -> 0 | Q18: =IF(Weights!$E18=0,0,$I18*Weights!Q18/Weights!$E18) -> 0 | ... GL18: =IF(Weights!$E18=0,0,$I18*Weights!GL18/Weights!$E18) -> 0
A19: NP-WHC | B19: 0-4005-02 | C19: PV | D19: 0-4005-02 Commish FOE | E19: 46542 | F19: 46624 | G19: 46542 | H19: 46624 | I19: 4260 | J19: =IF(Weights!$E19=0,0,$I19*Weights!J19/Weights!$E19) -> 0 | K19: =IF(Weights!$E19=0,0,$I19*Weights!K19/Weights!$E19) -> 0 | L19: =IF(Weights!$E19=0,0,$I19*Weights!L19/Weights!$E19) -> 0 | M19: =IF(Weights!$E19=0,0,$I19*Weights!M19/Weights!$E19) -> 0 | N19: =IF(Weights!$E19=0,0,$I19*Weights!N19/Weights!$E19) -> 0 | O19: =IF(Weights!$E19=0,0,$I19*Weights!O19/Weights!$E19) -> 0 | P19: =IF(Weights!$E19=0,0,$I19*Weights!P19/Weights!$E19) -> 0 | Q19: =IF(Weights!$E19=0,0,$I19*Weights!Q19/Weights!$E19) -> 0 | ... GL19: =IF(Weights!$E19=0,0,$I19*Weights!GL19/Weights!$E19) -> 0
A20: NP-WHC | B20: 0-4006 | C20: PV | D20: 0-4006-Yard and Trailer | G20: 46301 | H20: 46427 | I20: 8000 | J20: =IF(Weights!$E20=0,0,$I20*Weights!J20/Weights!$E20) -> 0 | K20: =IF(Weights!$E20=0,0,$I20*Weights!K20/Weights!$E20) -> 0 | L20: =IF(Weights!$E20=0,0,$I20*Weights!L20/Weights!$E20) -> 0 | M20: =IF(Weights!$E20=0,0,$I20*Weights!M20/Weights!$E20) -> 0 | N20: =IF(Weights!$E20=0,0,$I20*Weights!N20/Weights!$E20) -> 0 | O20: =IF(Weights!$E20=0,0,$I20*Weights!O20/Weights!$E20) -> 0 | P20: =IF(Weights!$E20=0,0,$I20*Weights!P20/Weights!$E20) -> 0 | Q20: =IF(Weights!$E20=0,0,$I20*Weights!Q20/Weights!$E20) -> 0 | ... GL20: =IF(Weights!$E20=0,0,$I20*Weights!GL20/Weights!$E20) -> 0
A21: NP-WHC | B21: 0-4007 | C21: Civil | D21: 0-4007-Mowing | G21: 46301 | H21: 46427 | I21: 3450 | J21: =IF(Weights!$E21=0,0,$I21*Weights!J21/Weights!$E21) -> 0 | K21: =IF(Weights!$E21=0,0,$I21*Weights!K21/Weights!$E21) -> 0 | L21: =IF(Weights!$E21=0,0,$I21*Weights!L21/Weights!$E21) -> 0 | M21: =IF(Weights!$E21=0,0,$I21*Weights!M21/Weights!$E21) -> 0 | N21: =IF(Weights!$E21=0,0,$I21*Weights!N21/Weights!$E21) -> 0 | O21: =IF(Weights!$E21=0,0,$I21*Weights!O21/Weights!$E21) -> 0 | P21: =IF(Weights!$E21=0,0,$I21*Weights!P21/Weights!$E21) -> 0 | Q21: =IF(Weights!$E21=0,0,$I21*Weights!Q21/Weights!$E21) -> 0 | ... GL21: =IF(Weights!$E21=0,0,$I21*Weights!GL21/Weights!$E21) -> 0
A22: NP-WHC | B22: 0-4010 | C22: Civil | I22: 0 | J22: =IF(Weights!$E22=0,0,$I22*Weights!J22/Weights!$E22) -> 0 | K22: =IF(Weights!$E22=0,0,$I22*Weights!K22/Weights!$E22) -> 0 | L22: =IF(Weights!$E22=0,0,$I22*Weights!L22/Weights!$E22) -> 0 | M22: =IF(Weights!$E22=0,0,$I22*Weights!M22/Weights!$E22) -> 0 | N22: =IF(Weights!$E22=0,0,$I22*Weights!N22/Weights!$E22) -> 0 | O22: =IF(Weights!$E22=0,0,$I22*Weights!O22/Weights!$E22) -> 0 | P22: =IF(Weights!$E22=0,0,$I22*Weights!P22/Weights!$E22) -> 0 | Q22: =IF(Weights!$E22=0,0,$I22*Weights!Q22/Weights!$E22) -> 0 | ... GL22: =IF(Weights!$E22=0,0,$I22*Weights!GL22/Weights!$E22) -> 0
A23: NP-WHC | B23: 0-4008 | C23: General | I23: 0 | J23: =IF(Weights!$E23=0,0,$I23*Weights!J23/Weights!$E23) -> 0 | K23: =IF(Weights!$E23=0,0,$I23*Weights!K23/Weights!$E23) -> 0 | L23: =IF(Weights!$E23=0,0,$I23*Weights!L23/Weights!$E23) -> 0 | M23: =IF(Weights!$E23=0,0,$I23*Weights!M23/Weights!$E23) -> 0 | N23: =IF(Weights!$E23=0,0,$I23*Weights!N23/Weights!$E23) -> 0 | O23: =IF(Weights!$E23=0,0,$I23*Weights!O23/Weights!$E23) -> 0 | P23: =IF(Weights!$E23=0,0,$I23*Weights!P23/Weights!$E23) -> 0 | Q23: =IF(Weights!$E23=0,0,$I23*Weights!Q23/Weights!$E23) -> 0 | ... GL23: =IF(Weights!$E23=0,0,$I23*Weights!GL23/Weights!$E23) -> 0
A24: PD-WHC | B24: 0-4013 | C24: PV | I24: 0 | J24: =IF(Weights!$E24=0,0,$I24*Weights!J24/Weights!$E24) -> 0 | K24: =IF(Weights!$E24=0,0,$I24*Weights!K24/Weights!$E24) -> 0 | L24: =IF(Weights!$E24=0,0,$I24*Weights!L24/Weights!$E24) -> 0 | M24: =IF(Weights!$E24=0,0,$I24*Weights!M24/Weights!$E24) -> 0 | N24: =IF(Weights!$E24=0,0,$I24*Weights!N24/Weights!$E24) -> 0 | O24: =IF(Weights!$E24=0,0,$I24*Weights!O24/Weights!$E24) -> 0 | P24: =IF(Weights!$E24=0,0,$I24*Weights!P24/Weights!$E24) -> 0 | Q24: =IF(Weights!$E24=0,0,$I24*Weights!Q24/Weights!$E24) -> 0 | ... GL24: =IF(Weights!$E24=0,0,$I24*Weights!GL24/Weights!$E24) -> 0
A25: PD-SUB | B25: 0-4013-01 | C25: PV | I25: 0 | J25: =IF(Weights!$E25=0,0,$I25*Weights!J25/Weights!$E25) -> 0 | K25: =IF(Weights!$E25=0,0,$I25*Weights!K25/Weights!$E25) -> 0 | L25: =IF(Weights!$E25=0,0,$I25*Weights!L25/Weights!$E25) -> 0 | M25: =IF(Weights!$E25=0,0,$I25*Weights!M25/Weights!$E25) -> 0 | N25: =IF(Weights!$E25=0,0,$I25*Weights!N25/Weights!$E25) -> 0 | O25: =IF(Weights!$E25=0,0,$I25*Weights!O25/Weights!$E25) -> 0 | P25: =IF(Weights!$E25=0,0,$I25*Weights!P25/Weights!$E25) -> 0 | Q25: =IF(Weights!$E25=0,0,$I25*Weights!Q25/Weights!$E25) -> 0 | ... GL25: =IF(Weights!$E25=0,0,$I25*Weights!GL25/Weights!$E25) -> 0
A26: PD-WHC | B26: 0-4013-02 | C26: PV | I26: 0 | J26: =IF(Weights!$E26=0,0,$I26*Weights!J26/Weights!$E26) -> 0 | K26: =IF(Weights!$E26=0,0,$I26*Weights!K26/Weights!$E26) -> 0 | L26: =IF(Weights!$E26=0,0,$I26*Weights!L26/Weights!$E26) -> 0 | M26: =IF(Weights!$E26=0,0,$I26*Weights!M26/Weights!$E26) -> 0 | N26: =IF(Weights!$E26=0,0,$I26*Weights!N26/Weights!$E26) -> 0 | O26: =IF(Weights!$E26=0,0,$I26*Weights!O26/Weights!$E26) -> 0 | P26: =IF(Weights!$E26=0,0,$I26*Weights!P26/Weights!$E26) -> 0 | Q26: =IF(Weights!$E26=0,0,$I26*Weights!Q26/Weights!$E26) -> 0 | ... GL26: =IF(Weights!$E26=0,0,$I26*Weights!GL26/Weights!$E26) -> 0
A27: PD-WHC | B27: 0-4015 | C27: PV | D27: 0-4015-Survey | G27: 46328 | H27: 46531 | I27: 2250 | J27: =IF(Weights!$E27=0,0,$I27*Weights!J27/Weights!$E27) -> 0 | K27: =IF(Weights!$E27=0,0,$I27*Weights!K27/Weights!$E27) -> 0 | L27: =IF(Weights!$E27=0,0,$I27*Weights!L27/Weights!$E27) -> 0 | M27: =IF(Weights!$E27=0,0,$I27*Weights!M27/Weights!$E27) -> 0 | N27: =IF(Weights!$E27=0,0,$I27*Weights!N27/Weights!$E27) -> 0 | O27: =IF(Weights!$E27=0,0,$I27*Weights!O27/Weights!$E27) -> 0 | P27: =IF(Weights!$E27=0,0,$I27*Weights!P27/Weights!$E27) -> 0 | Q27: =IF(Weights!$E27=0,0,$I27*Weights!Q27/Weights!$E27) -> 0 | ... GL27: =IF(Weights!$E27=0,0,$I27*Weights!GL27/Weights!$E27) -> 0
A28: PD-WHC | B28: 0-4015-01 | C28: Civil | D28: 0-4015-01-Civil Survey | G28: 46301 | H28: 46326 | I28: 1520 | J28: =IF(Weights!$E28=0,0,$I28*Weights!J28/Weights!$E28) -> 0 | K28: =IF(Weights!$E28=0,0,$I28*Weights!K28/Weights!$E28) -> 0 | L28: =IF(Weights!$E28=0,0,$I28*Weights!L28/Weights!$E28) -> 0 | M28: =IF(Weights!$E28=0,0,$I28*Weights!M28/Weights!$E28) -> 0 | N28: =IF(Weights!$E28=0,0,$I28*Weights!N28/Weights!$E28) -> 0 | O28: =IF(Weights!$E28=0,0,$I28*Weights!O28/Weights!$E28) -> 0 | P28: =IF(Weights!$E28=0,0,$I28*Weights!P28/Weights!$E28) -> 0 | Q28: =IF(Weights!$E28=0,0,$I28*Weights!Q28/Weights!$E28) -> 0 | ... GL28: =IF(Weights!$E28=0,0,$I28*Weights!GL28/Weights!$E28) -> 0
A29: PD-WHC | B29: 0-4016 | C29: PV | I29: 0 | J29: =IF(Weights!$E29=0,0,$I29*Weights!J29/Weights!$E29) -> 0 | K29: =IF(Weights!$E29=0,0,$I29*Weights!K29/Weights!$E29) -> 0 | L29: =IF(Weights!$E29=0,0,$I29*Weights!L29/Weights!$E29) -> 0 | M29: =IF(Weights!$E29=0,0,$I29*Weights!M29/Weights!$E29) -> 0 | N29: =IF(Weights!$E29=0,0,$I29*Weights!N29/Weights!$E29) -> 0 | O29: =IF(Weights!$E29=0,0,$I29*Weights!O29/Weights!$E29) -> 0 | P29: =IF(Weights!$E29=0,0,$I29*Weights!P29/Weights!$E29) -> 0 | Q29: =IF(Weights!$E29=0,0,$I29*Weights!Q29/Weights!$E29) -> 0 | ... GL29: =IF(Weights!$E29=0,0,$I29*Weights!GL29/Weights!$E29) -> 0
A30: PD-WHC | B30: 0-4018 | C30: General | I30: 0 | J30: =IF(Weights!$E30=0,0,$I30*Weights!J30/Weights!$E30) -> 0 | K30: =IF(Weights!$E30=0,0,$I30*Weights!K30/Weights!$E30) -> 0 | L30: =IF(Weights!$E30=0,0,$I30*Weights!L30/Weights!$E30) -> 0 | M30: =IF(Weights!$E30=0,0,$I30*Weights!M30/Weights!$E30) -> 0 | N30: =IF(Weights!$E30=0,0,$I30*Weights!N30/Weights!$E30) -> 0 | O30: =IF(Weights!$E30=0,0,$I30*Weights!O30/Weights!$E30) -> 0 | P30: =IF(Weights!$E30=0,0,$I30*Weights!P30/Weights!$E30) -> 0 | Q30: =IF(Weights!$E30=0,0,$I30*Weights!Q30/Weights!$E30) -> 0 | ... GL30: =IF(Weights!$E30=0,0,$I30*Weights!GL30/Weights!$E30) -> 0
A31: PD-WHC | B31: 0-4024 | C31: PV | I31: 0 | J31: =IF(Weights!$E31=0,0,$I31*Weights!J31/Weights!$E31) -> 0 | K31: =IF(Weights!$E31=0,0,$I31*Weights!K31/Weights!$E31) -> 0 | L31: =IF(Weights!$E31=0,0,$I31*Weights!L31/Weights!$E31) -> 0 | M31: =IF(Weights!$E31=0,0,$I31*Weights!M31/Weights!$E31) -> 0 | N31: =IF(Weights!$E31=0,0,$I31*Weights!N31/Weights!$E31) -> 0 | O31: =IF(Weights!$E31=0,0,$I31*Weights!O31/Weights!$E31) -> 0 | P31: =IF(Weights!$E31=0,0,$I31*Weights!P31/Weights!$E31) -> 0 | Q31: =IF(Weights!$E31=0,0,$I31*Weights!Q31/Weights!$E31) -> 0 | ... GL31: =IF(Weights!$E31=0,0,$I31*Weights!GL31/Weights!$E31) -> 0
A32: PD-WHC | B32: 0-4029 | C32: PV | I32: 0 | J32: =IF(Weights!$E32=0,0,$I32*Weights!J32/Weights!$E32) -> 0 | K32: =IF(Weights!$E32=0,0,$I32*Weights!K32/Weights!$E32) -> 0 | L32: =IF(Weights!$E32=0,0,$I32*Weights!L32/Weights!$E32) -> 0 | M32: =IF(Weights!$E32=0,0,$I32*Weights!M32/Weights!$E32) -> 0 | N32: =IF(Weights!$E32=0,0,$I32*Weights!N32/Weights!$E32) -> 0 | O32: =IF(Weights!$E32=0,0,$I32*Weights!O32/Weights!$E32) -> 0 | P32: =IF(Weights!$E32=0,0,$I32*Weights!P32/Weights!$E32) -> 0 | Q32: =IF(Weights!$E32=0,0,$I32*Weights!Q32/Weights!$E32) -> 0 | ... GL32: =IF(Weights!$E32=0,0,$I32*Weights!GL32/Weights!$E32) -> 0
A33: PD-WHC | B33: 0-4031 | C33: General | D33: 0-4031-Hire-In and Orientation | G33: 46328 | H33: 46531 | I33: 1616 | J33: =IF(Weights!$E33=0,0,$I33*Weights!J33/Weights!$E33) -> 0 | K33: =IF(Weights!$E33=0,0,$I33*Weights!K33/Weights!$E33) -> 0 | L33: =IF(Weights!$E33=0,0,$I33*Weights!L33/Weights!$E33) -> 0 | M33: =IF(Weights!$E33=0,0,$I33*Weights!M33/Weights!$E33) -> 0 | N33: =IF(Weights!$E33=0,0,$I33*Weights!N33/Weights!$E33) -> 0 | O33: =IF(Weights!$E33=0,0,$I33*Weights!O33/Weights!$E33) -> 0 | P33: =IF(Weights!$E33=0,0,$I33*Weights!P33/Weights!$E33) -> 0 | Q33: =IF(Weights!$E33=0,0,$I33*Weights!Q33/Weights!$E33) -> 0 | ... GL33: =IF(Weights!$E33=0,0,$I33*Weights!GL33/Weights!$E33) -> 0
A34: NP-WHC | B34: 0-4115 | C34: PV | D34: 0-4115-Clean Up | E34: 46540 | F34: 46637 | G34: 46540 | H34: 46637 | I34: 1800 | J34: =IF(Weights!$E34=0,0,$I34*Weights!J34/Weights!$E34) -> 0 | K34: =IF(Weights!$E34=0,0,$I34*Weights!K34/Weights!$E34) -> 0 | L34: =IF(Weights!$E34=0,0,$I34*Weights!L34/Weights!$E34) -> 0 | M34: =IF(Weights!$E34=0,0,$I34*Weights!M34/Weights!$E34) -> 0 | N34: =IF(Weights!$E34=0,0,$I34*Weights!N34/Weights!$E34) -> 0 | O34: =IF(Weights!$E34=0,0,$I34*Weights!O34/Weights!$E34) -> 0 | P34: =IF(Weights!$E34=0,0,$I34*Weights!P34/Weights!$E34) -> 0 | Q34: =IF(Weights!$E34=0,0,$I34*Weights!Q34/Weights!$E34) -> 0 | ... GL34: =IF(Weights!$E34=0,0,$I34*Weights!GL34/Weights!$E34) -> 0
A35: PD-WHC | B35: 0-4115-01 | C35: Civil | D35: 0-4115-01-Civil Cleanup | E35: 46540 | F35: 46637 | G35: 46540 | H35: 46637 | I35: 1860 | J35: =IF(Weights!$E35=0,0,$I35*Weights!J35/Weights!$E35) -> 0 | K35: =IF(Weights!$E35=0,0,$I35*Weights!K35/Weights!$E35) -> 0 | L35: =IF(Weights!$E35=0,0,$I35*Weights!L35/Weights!$E35) -> 0 | M35: =IF(Weights!$E35=0,0,$I35*Weights!M35/Weights!$E35) -> 0 | N35: =IF(Weights!$E35=0,0,$I35*Weights!N35/Weights!$E35) -> 0 | O35: =IF(Weights!$E35=0,0,$I35*Weights!O35/Weights!$E35) -> 0 | P35: =IF(Weights!$E35=0,0,$I35*Weights!P35/Weights!$E35) -> 0 | Q35: =IF(Weights!$E35=0,0,$I35*Weights!Q35/Weights!$E35) -> 0 | ... GL35: =IF(Weights!$E35=0,0,$I35*Weights!GL35/Weights!$E35) -> 0
A36: PD-WHC | B36: 0-4100 | C36: Civil | D36: 0-4100-Silt Fence | E36: 46298 | F36: 46319 | G36: 46298 | H36: 46319 | I36: 2940 | J36: =IF(Weights!$E36=0,0,$I36*Weights!J36/Weights!$E36) -> 0 | K36: =IF(Weights!$E36=0,0,$I36*Weights!K36/Weights!$E36) -> 0 | L36: =IF(Weights!$E36=0,0,$I36*Weights!L36/Weights!$E36) -> 0 | M36: =IF(Weights!$E36=0,0,$I36*Weights!M36/Weights!$E36) -> 0 | N36: =IF(Weights!$E36=0,0,$I36*Weights!N36/Weights!$E36) -> 0 | O36: =IF(Weights!$E36=0,0,$I36*Weights!O36/Weights!$E36) -> 0 | P36: =IF(Weights!$E36=0,0,$I36*Weights!P36/Weights!$E36) -> 0 | Q36: =IF(Weights!$E36=0,0,$I36*Weights!Q36/Weights!$E36) -> 0 | ... GL36: =IF(Weights!$E36=0,0,$I36*Weights!GL36/Weights!$E36) -> 0
A37: PD-WHC | B37: 0-4112 | C37: Civil | D37: 0-4112-Scour & Veg. Buffer | E37: 46329 | F37: 46360 | G37: 46329 | H37: 46360 | I37: 0 | J37: =IF(Weights!$E37=0,0,$I37*Weights!J37/Weights!$E37) -> 0 | K37: =IF(Weights!$E37=0,0,$I37*Weights!K37/Weights!$E37) -> 0 | L37: =IF(Weights!$E37=0,0,$I37*Weights!L37/Weights!$E37) -> 0 | M37: =IF(Weights!$E37=0,0,$I37*Weights!M37/Weights!$E37) -> 0 | N37: =IF(Weights!$E37=0,0,$I37*Weights!N37/Weights!$E37) -> 0 | O37: =IF(Weights!$E37=0,0,$I37*Weights!O37/Weights!$E37) -> 0 | P37: =IF(Weights!$E37=0,0,$I37*Weights!P37/Weights!$E37) -> 0 | Q37: =IF(Weights!$E37=0,0,$I37*Weights!Q37/Weights!$E37) -> 0 | ... GL37: =IF(Weights!$E37=0,0,$I37*Weights!GL37/Weights!$E37) -> 0
A38: PD-WHC | B38: 0-4101 | C38: Civil | D38: 0-4101-Clearing & Grubbing | E38: 46300 | F38: 46329 | G38: 46300 | H38: 46329 | I38: 600 | J38: =IF(Weights!$E38=0,0,$I38*Weights!J38/Weights!$E38) -> 0 | K38: =IF(Weights!$E38=0,0,$I38*Weights!K38/Weights!$E38) -> 0 | L38: =IF(Weights!$E38=0,0,$I38*Weights!L38/Weights!$E38) -> 0 | M38: =IF(Weights!$E38=0,0,$I38*Weights!M38/Weights!$E38) -> 0 | N38: =IF(Weights!$E38=0,0,$I38*Weights!N38/Weights!$E38) -> 0 | O38: =IF(Weights!$E38=0,0,$I38*Weights!O38/Weights!$E38) -> 0 | P38: =IF(Weights!$E38=0,0,$I38*Weights!P38/Weights!$E38) -> 0 | Q38: =IF(Weights!$E38=0,0,$I38*Weights!Q38/Weights!$E38) -> 0 | ... GL38: =IF(Weights!$E38=0,0,$I38*Weights!GL38/Weights!$E38) -> 0
A39: PD-WHC | B39: 0-4102 | C39: Civil | D39: 0-4102-Earth Work | G39: 46307 | H39: 46346 | I39: 6540 | J39: =IF(Weights!$E39=0,0,$I39*Weights!J39/Weights!$E39) -> 0 | K39: =IF(Weights!$E39=0,0,$I39*Weights!K39/Weights!$E39) -> 0 | L39: =IF(Weights!$E39=0,0,$I39*Weights!L39/Weights!$E39) -> 0 | M39: =IF(Weights!$E39=0,0,$I39*Weights!M39/Weights!$E39) -> 0 | N39: =IF(Weights!$E39=0,0,$I39*Weights!N39/Weights!$E39) -> 0 | O39: =IF(Weights!$E39=0,0,$I39*Weights!O39/Weights!$E39) -> 0 | P39: =IF(Weights!$E39=0,0,$I39*Weights!P39/Weights!$E39) -> 0 | Q39: =IF(Weights!$E39=0,0,$I39*Weights!Q39/Weights!$E39) -> 0 | ... GL39: =IF(Weights!$E39=0,0,$I39*Weights!GL39/Weights!$E39) -> 0
A40: PD-WHC | B40: 0-4103 | C40: Civil | D40: 0-4103-Erosion Control | E40: 46298 | F40: 46319 | G40: 46298 | H40: 46319 | I40: 1830 | J40: =IF(Weights!$E40=0,0,$I40*Weights!J40/Weights!$E40) -> 0 | K40: =IF(Weights!$E40=0,0,$I40*Weights!K40/Weights!$E40) -> 0 | L40: =IF(Weights!$E40=0,0,$I40*Weights!L40/Weights!$E40) -> 0 | M40: =IF(Weights!$E40=0,0,$I40*Weights!M40/Weights!$E40) -> 0 | N40: =IF(Weights!$E40=0,0,$I40*Weights!N40/Weights!$E40) -> 0 | O40: =IF(Weights!$E40=0,0,$I40*Weights!O40/Weights!$E40) -> 0 | P40: =IF(Weights!$E40=0,0,$I40*Weights!P40/Weights!$E40) -> 0 | Q40: =IF(Weights!$E40=0,0,$I40*Weights!Q40/Weights!$E40) -> 0 | ... GL40: =IF(Weights!$E40=0,0,$I40*Weights!GL40/Weights!$E40) -> 0
...

Sheet Holidays
A1: Holiday | B1: Date (Observed) | C1: Type | D1: Week Factor | F1: Week Factor Inputs
A2: New Year's Day | B2: 46023 | C2: Minor | D2: =IF(C2="Major",$G$3,$G$2) -> 0.8 | F2: Minor holiday week | G2: 0.8
A3: Memorial Day | B3: 46167 | C3: Minor | D3: =IF(C3="Major",$G$3,$G$2) -> 0.8 | F3: Major holiday week (skip) | G3: 0
A4: Independence Day | B4: 46206 | C4: Minor | D4: =IF(C4="Major",$G$3,$G$2) -> 0.8
A5: Labor Day | B5: 46272 | C5: Minor | D5: =IF(C5="Major",$G$3,$G$2) -> 0.8 | F5: Factor = share of a normal week's hours worked in that holiday's week (Mon–Sun). 0 = week skipped.
A6: Thanksgiving | B6: 46352 | C6: Major | D6: =IF(C6="Major",$G$3,$G$2) -> 0
A7: Christmas | B7: 46381 | C7: Major | D7: =IF(C7="Major",$G$3,$G$2) -> 0
A8: New Year's Day | B8: 46388 | C8: Minor | D8: =IF(C8="Major",$G$3,$G$2) -> 0.8
A9: Memorial Day | B9: 46538 | C9: Minor | D9: =IF(C9="Major",$G$3,$G$2) -> 0.8
A10: Independence Day | B10: 46573 | C10: Minor | D10: =IF(C10="Major",$G$3,$G$2) -> 0.8
A11: Labor Day | B11: 46636 | C11: Minor | D11: =IF(C11="Major",$G$3,$G$2) -> 0.8
A12: Thanksgiving | B12: 46716 | C12: Major | D12: =IF(C12="Major",$G$3,$G$2) -> 0
A13: Christmas | B13: 46745 | C13: Major | D13: =IF(C13="Major",$G$3,$G$2) -> 0
A14: New Year's Day | B14: 46752 | C14: Minor | D14: =IF(C14="Major",$G$3,$G$2) -> 0.8
A15: Memorial Day | B15: 46902 | C15: Minor | D15: =IF(C15="Major",$G$3,$G$2) -> 0.8
A16: Independence Day | B16: 46938 | C16: Minor | D16: =IF(C16="Major",$G$3,$G$2) -> 0.8
A17: Labor Day | B17: 47000 | C17: Minor | D17: =IF(C17="Major",$G$3,$G$2) -> 0.8
... A25: Christmas | B25: 47477 | C25: Major | D25: =IF(C25="Major",$G$3,$G$2) -> 0

Sheet Weights
A1: Cost Code | B1: Activity | C1: Curve | E1: Sum of Weights | G1: Start Date | H1: Finish Date | I1: Working Wks | J1: =Sheet1!J1 -> 46194 | K1: =Sheet1!K1 -> 46201 | L1: =Sheet1!L1 -> 46208 | M1: =Sheet1!M1 -> 46215 | N1: =Sheet1!N1 -> 46222 | O1: =Sheet1!O1 -> 46229 | P1: =Sheet1!P1 -> 46236 | Q1: =Sheet1!Q1 -> 46243 | ... GL1: =Sheet1!GL1 -> 47482
A2: =Sheet1!B2 -> 0 | B2: =Sheet1!D2 -> 0 | E2: =SUM(J2:GL2) -> 0 | G2: =IF(Sheet1!G2="","",Sheet1!G2) | H2: =IF(Sheet1!H2="","",Sheet1!H2) | I2: =IF(OR(G2="",H2=""),0,COUNTIFS($J$1:$GL$1,">="&G2,$J$1:$GL$1,"<="&H2+6,$J$140:$GL$140,">0")) -> 0 | J2: =IF($I2=0,0,IF(OR(J$140=0,J$1<$G2,J$1>$H2+6),0,_xlfn.LET(_xlpm.k,COUNTIFS($J$1:J$1,">="&$G2,$J$140:J$140,">0"),_xlpm.n,$I2,J$140*IF($C2="Bell",EXP(-0.5*((_xlpm.k-(_xlpm.n+1)/2)/MAX(_xlpm.n/6,0.5))^2),IF(_xlpm.n<=6,1,MIN(1,_xlpm.k/3,(_xlpm.n-_xlpm.k+1)/3)))))) -> 0 | K2: =IF($I2=0,0,IF(OR(K$140=0,K$1<$G2,K$1>$H2+6),0,_xlfn.LET(_xlpm.k,COUNTIFS($J$1:K$1,">="&$G2,$J$140:K$140,">0"),_xlpm.n,$I2,K$140*IF($C2="Bell",EXP(-0.5*((_xlpm.k-(_xlpm.n+1)/2)/MAX(_xlpm.n/6,0.5))^2),IF(_xlpm.n<=6,1,MIN(1,_xlpm.k/3,(_xlpm.n-_xlpm.k+1)/3)))))) -> 0 | L2: =IF($I2=0,0,IF(OR(L$140=0,L$1<$G2,L$1>$H2+6),0,_xlfn.LET(_xlpm.k,COUNTIFS($J$1:L$1,">="&$G2,$J$140:L$140,">0"),_xlpm.n,$I2,L$140*IF($C2="Bell",EXP(-0.5*((_xlpm.k-(_xlpm.n+1)/2)/MAX(_xlpm.n/6,0.5))^2),IF(_xlpm.n<=6,1,MIN(1,_xlpm.k/3,(_xlpm.n-_xlpm.k+1)/3)))))) -> 0 | M2: =IF($I2=0,0,IF(OR(M$140=0,M$1<$G2,M$1>$H2+6),0,_xlfn.LET(_xlpm.k,COUNTIFS($J$1:M$1,">="&$G2,$J$140:M$140,">0"),_xlpm.n,$I2,M$140*IF($C2="Bell",EXP(-0.5*((_xlpm.k-(_xlpm.n+1)/2)/MAX(_xlpm.n/6,0.5))^2),IF(_xlpm.n<=6,1,MIN(1,_xlpm.k/3,(_xlpm.n-_xlpm.k+1)/3)))))) -> 0 | N2: =IF($I2=0,0,IF(OR(N$140=0,N$1<$G2,N$1>$H2+6),0,_xlfn.LET(_xlpm.k,COUNTIFS($J$1:N$1,">="&$G2,$J$140:N$140,">0"),_xlpm.n,$I2,N$140*IF($C2="Bell",EXP(-0.5*((_xlpm.k-(_xlpm.n+1)/2)/MAX(_xlpm.n/6,0.5))^2),IF(_xlpm.n<=6,1,MIN(1,_xlpm.k/3,(_xlpm.n-_xlpm.k+1)/3)))))) -> 0 | O2: =IF($I2=0,0,IF(OR(O$140=0,O$1<$G2,O$1>$H2+6),0,_xlfn.LET(_xlpm.k,COUNTIFS($J$1:O$1,">="&$G2,$J$140:O$140,">0"),_xlpm.n,$I2,O$140*IF($C2="Bell",EXP(-0.5*((_xlpm.k-(_xlpm.n+1)/2)/MAX(_xlpm.n/6,0.5))^2),IF(_xlpm.n<=6,1,MIN(1,_xlpm.k/3,(_xlpm.n-_xlpm.k+1)/3)))))) -> 0 | P2: =IF($I2=0,0,IF(OR(P$140=0,P$1<$G2,P$1>$H2+6),0,_xlfn.LET(_xlpm.k,COUNTIFS($J$1:P$1,">="&$G2,$J$140:P$140,">0"),_xlpm.n,$I2,P$140*IF($C2="Bell",EXP(-0.5*((_xlpm.k-(_xlpm.n+1)/2)/MAX(_xlpm.n/6,0.5))^2),IF(_xlpm.n<=6,1,MIN(1,_xlpm.k/3,(_xlpm.n-_xlpm.k+1)/3)))))) -> 0 | Q2: =IF($I2=0,0,IF(OR(Q$140=0,Q$1<$G2,Q$1>$H2+6),0,_xlfn.LET(_xlpm.k,COUNTIFS($J$1:Q$1,">="&$G2,$J$140:Q$140,">0"),_xlpm.n,$I2,Q$140*IF($C2="Bell",EXP(-0.5*((_xlpm.k-(_xlpm.n+1)/2)/MAX(_xlpm.n/6,0.5))^2),IF(_xlpm.n<=6,1,MIN(1,_xlpm.k/3,(_xlpm.n-_xlpm.k+1)/3)))))) -> 0 | ... GL2: =IF($I2=0,0,IF(OR(GL$140=0,GL$1<$G2,GL$1>$H2+6),0,_xlfn.LET(_xlpm.k,COUNTIFS($J$1:GL$1,">="&$G2,$J$140:GL$140,">0"),_xlpm.n,$I2,GL$140*IF($C2="Bell",EXP(-0.5*((_xlpm.k-(_xlpm.n+1)/2)/MAX(_xlpm.n/6,0.5))^2),IF(_xlpm.n<=6,1,MIN(1,_xlpm.k/3,(_xlpm.n-_xlpm.k+1)/3)))))) -> 0
A3: =Sheet1!B3 -> 0 | B3: =Sheet1!D3 -> 0 | E3: =SUM(J3:GL3) -> 0 | G3: =IF(Sheet1!G3="","",Sheet1!G3) | H3: =IF(Sheet1!H3="","",Sheet1!H3) | I3: =IF(OR(G3="",H3=""),0,COUNTIFS($J$1:$GL$1,">="&G3,$J$1:$GL$1,"<="&H3+6,$J$140:$GL$140,">0")) -> 0 | J3: =IF($I3=0,0,IF(OR(J$140=0,J$1<$G3,J$1>$H3+6),0,_xlfn.LET(_xlpm.k,COUNTIFS($J$1:J$1,">="&$G3,$J$140:J$140,">0"),_xlpm.n,$I3,J$140*IF($C3="Bell",EXP(-0.5*((_xlpm.k-(_xlpm.n+1)/2)/MAX(_xlpm.n/6,0.5))^2),IF(_xlpm.n<=6,1,MIN(1,_xlpm.k/3,(_xlpm.n-_xlpm.k+1)/3)))))) -> 0 | K3: =IF($I3=0,0,IF(OR(K$140=0,K$1<$G3,K$1>$H3+6),0,_xlfn.LET(_xlpm.k,COUNTIFS($J$1:K$1,">="&$G3,$J$140:K$140,">0"),_xlpm.n,$I3,K$140*IF($C3="Bell",EXP(-0.5*((_xlpm.k-(_xlpm.n+1)/2)/MAX(_xlpm.n/6,0.5))^2),IF(_xlpm.n<=6,1,MIN(1,_xlpm.k/3,(_xlpm.n-_xlpm.k+1)/3)))))) -> 0 | L3: =IF($I3=0,0,IF(OR(L$140=0,L$1<$G3,L$1>$H3+6),0,_xlfn.LET(_xlpm.k,COUNTIFS($J$1:L$1,">="&$G3,$J$140:L$140,">0"),_xlpm.n,$I3,L$140*IF($C3="Bell",EXP(-0.5*((_xlpm.k-(_xlpm.n+1)/2)/MAX(_xlpm.n/6,0.5))^2),IF(_xlpm.n<=6,1,MIN(1,_xlpm.k/3,(_xlpm.n-_xlpm.k+1)/3)))))) -> 0 | M3: =IF($I3=0,0,IF(OR(M$140=0,M$1<$G3,M$1>$H3+6),0,_xlfn.LET(_xlpm.k,COUNTIFS($J$1:M$1,">="&$G3,$J$140:M$140,">0"),_xlpm.n,$I3,M$140*IF($C3="Bell",EXP(-0.5*((_xlpm.k-(_xlpm.n+1)/2)/MAX(_xlpm.n/6,0.5))^2),IF(_xlpm.n<=6,1,MIN(1,_xlpm.k/3,(_xlpm.n-_xlpm.k+1)/3)))))) -> 0 | N3: =IF($I3=0,0,IF(OR(N$140=0,N$1<$G3,N$1>$H3+6),0,_xlfn.LET(_xlpm.k,COUNTIFS($J$1:N$1,">="&$G3,$J$140:N$140,">0"),_xlpm.n,$I3,N$140*IF($C3="Bell",EXP(-0.5*((_xlpm.k-(_xlpm.n+1)/2)/MAX(_xlpm.n/6,0.5))^2),IF(_xlpm.n<=6,1,MIN(1,_xlpm.k/3,(_xlpm.n-_xlpm.k+1)/3)))))) -> 0 | O3: =IF($I3=0,0,IF(OR(O$140=0,O$1<$G3,O$1>$H3+6),0,_xlfn.LET(_xlpm.k,COUNTIFS($J$1:O$1,">="&$G3,$J$140:O$140,">0"),_xlpm.n,$I3,O$140*IF($C3="Bell",EXP(-0.5*((_xlpm.k-(_xlpm.n+1)/2)/MAX(_xlpm.n/6,0.5))^2),IF(_xlpm.n<=6,1,MIN(1,_xlpm.k/3,(_xlpm.n-_xlpm.k+1)/3)))))) -> 0 | P3: =IF($I3=0,0,IF(OR(P$140=0,P$1<$G3,P$1>$H3+6),0,_xlfn.LET(_xlpm.k,COUNTIFS($J$1:P$1,">="&$G3,$J$140:P$140,">0"),_xlpm.n,$I3,P$140*IF($C3="Bell",EXP(-0.5*((_xlpm.k-(_xlpm.n+1)/2)/MAX(_xlpm.n/6,0.5))^2),IF(_xlpm.n<=6,1,MIN(1,_xlpm.k/3,(_xlpm.n-_xlpm.k+1)/3)))))) -> 0 | Q3: =IF($I3=0,0,IF(OR(Q$140=0,Q$1<$G3,Q$1>$H3+6),0,_xlfn.LET(_xlpm.k,COUNTIFS($J$1:Q$1,">="&$G3,$J$140:Q$140,">0"),_xlpm.n,$I3,Q$140*IF($C3="Bell",EXP(-0.5*((_xlpm.k-(_xlpm.n+1)/2)/MAX(_xlpm.n/6,0.5))^2),IF(_xlpm.n<=6,1,MIN(1,_xlpm.k/3,(_xlpm.n-_xlpm.k+1)/3)))))) -> 0 | ... GL3: =IF($I3=0,0,IF(OR(GL$140=0,GL$1<$G3,GL$1>$H3+6),0,_xlfn.LET(_xlpm.k,COUNTIFS($J$1:GL$1,">="&$G3,$J$140:GL$140,">0"),_xlpm.n,$I3,GL$140*IF($C3="Bell",EXP(-0.5*((_xlpm.k-(_xlpm.n+1)/2)/MAX(_xlpm.n/6,0.5))^2),IF(_xlpm.n<=6,1,MIN(1,_xlpm.k/3,(_xlpm.n-_xlpm.k+1)/3)))))) -> 0
A4: =Sheet1!B4 -> 0-4000-01 | B4: =Sheet1!D4 -> 0-4000-01-Mobilization | E4: =SUM(J4:GL4) -> 4 | G4: =IF(Sheet1!G4="","",Sheet1!G4) -> 46300 | H4: =IF(Sheet1!H4="","",Sheet1!H4) -> 46325 | I4: =IF(OR(G4="",H4=""),0,COUNTIFS($J$1:$GL$1,">="&G4,$J$1:$GL$1,"<="&H4+6,$J$140:$GL$140,">0")) -> 4 | J4: =IF($I4=0,0,IF(OR(J$140=0,J$1<$G4,J$1>$H4+6),0,_xlfn.LET(_xlpm.k,COUNTIFS($J$1:J$1,">="&$G4,$J$140:J$140,">0"),_xlpm.n,$I4,J$140*IF($C4="Bell",EXP(-0.5*((_xlpm.k-(_xlpm.n+1)/2)/MAX(_xlpm.n/6,0.5))^2),IF(_xlpm.n<=6,1,MIN(1,_xlpm.k/3,(_xlpm.n-_xlpm.k+1)/3)))))) -> 0 | K4: =IF($I4=0,0,IF(OR(K$140=0,K$1<$G4,K$1>$H4+6),0,_xlfn.LET(_xlpm.k,COUNTIFS($J$1:K$1,">="&$G4,$J$140:K$140,">0"),_xlpm.n,$I4,K$140*IF($C4="Bell",EXP(-0.5*((_xlpm.k-(_xlpm.n+1)/2)/MAX(_xlpm.n/6,0.5))^2),IF(_xlpm.n<=6,1,MIN(1,_xlpm.k/3,(_xlpm.n-_xlpm.k+1)/3)))))) -> 0 | L4: =IF($I4=0,0,IF(OR(L$140=0,L$1<$G4,L$1>$H4+6),0,_xlfn.LET(_xlpm.k,COUNTIFS($J$1:L$1,">="&$G4,$J$140:L$140,">0"),_xlpm.n,$I4,L$140*IF($C4="Bell",EXP(-0.5*((_xlpm.k-(_xlpm.n+1)/2)/MAX(_xlpm.n/6,0.5))^2),IF(_xlpm.n<=6,1,MIN(1,_xlpm.k/3,(_xlpm.n-_xlpm.k+1)/3)))))) -> 0 | M4: =IF($I4=0,0,IF(OR(M$140=0,M$1<$G4,M$1>$H4+6),0,_xlfn.LET(_xlpm.k,COUNTIFS($J$1:M$1,">="&$G4,$J$140:M$140,">0"),_xlpm.n,$I4,M$140*IF($C4="Bell",EXP(-0.5*((_xlpm.k-(_xlpm.n+1)/2)/MAX(_xlpm.n/6,0.5))^2),IF(_xlpm.n<=6,1,MIN(1,_xlpm.k/3,(_xlpm.n-_xlpm.k+1)/3)))))) -> 0 | N4: =IF($I4=0,0,IF(OR(N$140=0,N$1<$G4,N$1>$H4+6),0,_xlfn.LET(_xlpm.k,COUNTIFS($J$1:N$1,">="&$G4,$J$140:N$140,">0"),_xlpm.n,$I4,N$140*IF($C4="Bell",EXP(-0.5*((_xlpm.k-(_xlpm.n+1)/2)/MAX(_xlpm.n/6,0.5))^2),IF(_xlpm.n<=6,1,MIN(1,_xlpm.k/3,(_xlpm.n-_xlpm.k+1)/3)))))) -> 0 | O4: =IF($I4=0,0,IF(OR(O$140=0,O$1<$G4,O$1>$H4+6),0,_xlfn.LET(_xlpm.k,COUNTIFS($J$1:O$1,">="&$G4,$J$140:O$140,">0"),_xlpm.n,$I4,O$140*IF($C4="Bell",EXP(-0.5*((_xlpm.k-(_xlpm.n+1)/2)/MAX(_xlpm.n/6,0.5))^2),IF(_xlpm.n<=6,1,MIN(1,_xlpm.k/3,(_xlpm.n-_xlpm.k+1)/3)))))) -> 0 | P4: =IF($I4=0,0,IF(OR(P$140=0,P$1<$G4,P$1>$H4+6),0,_xlfn.LET(_xlpm.k,COUNTIFS($J$1:P$1,">="&$G4,$J$140:P$140,">0"),_xlpm.n,$I4,P$140*IF($C4="Bell",EXP(-0.5*((_xlpm.k-(_xlpm.n+1)/2)/MAX(_xlpm.n/6,0.5))^2),IF(_xlpm.n<=6,1,MIN(1,_xlpm.k/3,(_xlpm.n-_xlpm.k+1)/3)))))) -> 0 | Q4: =IF($I4=0,0,IF(OR(Q$140=0,Q$1<$G4,Q$1>$H4+6),0,_xlfn.LET(_xlpm.k,COUNTIFS($J$1:Q$1,">="&$G4,$J$140:Q$140,">0"),_xlpm.n,$I4,Q$140*IF($C4="Bell",EXP(-0.5*((_xlpm.k-(_xlpm.n+1)/2)/MAX(_xlpm.n/6,0.5))^2),IF(_xlpm.n<=6,1,MIN(1,_xlpm.k/3,(_xlpm.n-_xlpm.k+1)/3)))))) -> 0 | ... GL4: =IF($I4=0,0,IF(OR(GL$140=0,GL$1<$G4,GL$1>$H4+6),0,_xlfn.LET(_xlpm.k,COUNTIFS($J$1:GL$1,">="&$G4,$J$140:GL$140,">0"),_xlpm.n,$I4,GL$140*IF($C4="Bell",EXP(-0.5*((_xlpm.k-(_xlpm.n+1)/2)/MAX(_xlpm.n/6,0.5))^2),IF(_xlpm.n<=6,1,MIN(1,_xlpm.k/3,(_xlpm.n-_xlpm.k+1)/3)))))) -> 0
A5: =Sheet1!B5 -> 0-4001-01 | B5: =Sheet1!D5 -> 0-4001-01-DeMobilization | E5: =SUM(J5:GL5) -> 0.8 | G5: =IF(Sheet1!G5="","",Sheet1!G5) -> 46637 | H5: =IF(Sheet1!H5="","",Sheet1!H5) -> 46637 | I5: =IF(OR(G5="",H5=""),0,COUNTIFS($J$1:$GL$1,">="&G5,$J$1:$GL$1,"<="&H5+6,$J$140:$GL$140,">0")) -> 1 | J5: =IF($I5=0,0,IF(OR(J$140=0,J$1<$G5,J$1>$H5+6),0,_xlfn.LET(_xlpm.k,COUNTIFS($J$1:J$1,">="&$G5,$J$140:J$140,">0"),_xlpm.n,$I5,J$140*IF($C5="Bell",EXP(-0.5*((_xlpm.k-(_xlpm.n+1)/2)/MAX(_xlpm.n/6,0.5))^2),IF(_xlpm.n<=6,1,MIN(1,_xlpm.k/3,(_xlpm.n-_xlpm.k+1)/3)))))) -> 0 | K5: =IF($I5=0,0,IF(OR(K$140=0,K$1<$G5,K$1>$H5+6),0,_xlfn.LET(_xlpm.k,COUNTIFS($J$1:K$1,">="&$G5,$J$140:K$140,">0"),_xlpm.n,$I5,K$140*IF($C5="Bell",EXP(-0.5*((_xlpm.k-(_xlpm.n+1)/2)/MAX(_xlpm.n/6,0.5))^2),IF(_xlpm.n<=6,1,MIN(1,_xlpm.k/3,(_xlpm.n-_xlpm.k+1)/3)))))) -> 0 | L5: =IF($I5=0,0,IF(OR(L$140=0,L$1<$G5,L$1>$H5+6),0,_xlfn.LET(_xlpm.k,COUNTIFS($J$1:L$1,">="&$G5,$J$140:L$140,">0"),_xlpm.n,$I5,L$140*IF($C5="Bell",EXP(-0.5*((_xlpm.k-(_xlpm.n+1)/2)/MAX(_xlpm.n/6,0.5))^2),IF(_xlpm.n<=6,1,MIN(1,_xlpm.k/3,(_xlpm.n-_xlpm.k+1)/3)))))) -> 0 | M5: =IF($I5=0,0,IF(OR(M$140=0,M$1<$G5,M$1>$H5+6),0,_xlfn.LET(_xlpm.k,COUNTIFS($J$1:M$1,">="&$G5,$J$140:M$140,">0"),_xlpm.n,$I5,M$140*IF($C5="Bell",EXP(-0.5*((_xlpm.k-(_xlpm.n+1)/2)/MAX(_xlpm.n/6,0.5))^2),IF(_xlpm.n<=6,1,MIN(1,_xlpm.k/3,(_xlpm.n-_xlpm.k+1)/3)))))) -> 0 | N5: =IF($I5=0,0,IF(OR(N$140=0,N$1<$G5,N$1>$H5+6),0,_xlfn.LET(_xlpm.k,COUNTIFS($J$1:N$1,">="&$G5,$J$140:N$140,">0"),_xlpm.n,$I5,N$140*IF($C5="Bell",EXP(-0.5*((_xlpm.k-(_xlpm.n+1)/2)/MAX(_xlpm.n/6,0.5))^2),IF(_xlpm.n<=6,1,MIN(1,_xlpm.k/3,(_xlpm.n-_xlpm.k+1)/3)))))) -> 0 | O5: =IF($I5=0,0,IF(OR(O$140=0,O$1<$G5,O$1>$H5+6),0,_xlfn.LET(_xlpm.k,COUNTIFS($J$1:O$1,">="&$G5,$J$140:O$140,">0"),_xlpm.n,$I5,O$140*IF($C5="Bell",EXP(-0.5*((_xlpm.k-(_xlpm.n+1)/2)/MAX(_xlpm.n/6,0.5))^2),IF(_xlpm.n<=6,1,MIN(1,_xlpm.k/3,(_xlpm.n-_xlpm.k+1)/3)))))) -> 0 | P5: =IF($I5=0,0,IF(OR(P$140=0,P$1<$G5,P$1>$H5+6),0,_xlfn.LET(_xlpm.k,COUNTIFS($J$1:P$1,">="&$G5,$J$140:P$140,">0"),_xlpm.n,$I5,P$140*IF($C5="Bell",EXP(-0.5*((_xlpm.k-(_xlpm.n+1)/2)/MAX(_xlpm.n/6,0.5))^2),IF(_xlpm.n<=6,1,MIN(1,_xlpm.k/3,(_xlpm.n-_xlpm.k+1)/3)))))) -> 0 | Q5: =IF($I5=0,0,IF(OR(Q$140=0,Q$1<$G5,Q$1>$H5+6),0,_xlfn.LET(_xlpm.k,COUNTIFS($J$1:Q$1,">="&$G5,$J$140:Q$140,">0"),_xlpm.n,$I5,Q$140*IF($C5="Bell",EXP(-0.5*((_xlpm.k-(_xlpm.n+1)/2)/MAX(_xlpm.n/6,0.5))^2),IF(_xlpm.n<=6,1,MIN(1,_xlpm.k/3,(_xlpm.n-_xlpm.k+1)/3)))))) -> 0 | ... GL5: =IF($I5=0,0,IF(OR(GL$140=0,GL$1<$G5,GL$1>$H5+6),0,_xlfn.LET(_xlpm.k,COUNTIFS($J$1:GL$1,">="&$G5,$J$140:GL$140,">0"),_xlpm.n,$I5,GL$140*IF($C5="Bell",EXP(-0.5*((_xlpm.k-(_xlpm.n+1)/2)/MAX(_xlpm.n/6,0.5))^2),IF(_xlpm.n<=6,1,MIN(1,_xlpm.k/3,(_xlpm.n-_xlpm.k+1)/3)))))) -> 0
A6: =Sheet1!B6 -> 0-4004-01 | B6: =Sheet1!D6 -> 0 | E6: =SUM(J6:GL6) -> 0 | G6: =IF(Sheet1!G6="","",Sheet1!G6) | H6: =IF(Sheet1!H6="","",Sheet1!H6) | I6: =IF(OR(G6="",H6=""),0,COUNTIFS($J$1:$GL$1,">="&G6,$J$1:$GL$1,"<="&H6+6,$J$140:$GL$140,">0")) -> 0 | J6: =IF($I6=0,0,IF(OR(J$140=0,J$1<$G6,J$1>$H6+6),0,_xlfn.LET(_xlpm.k,COUNTIFS($J$1:J$1,">="&$G6,$J$140:J$140,">0"),_xlpm.n,$I6,J$140*IF($C6="Bell",EXP(-0.5*((_xlpm.k-(_xlpm.n+1)/2)/MAX(_xlpm.n/6,0.5))^2),IF(_xlpm.n<=6,1,MIN(1,_xlpm.k/3,(_xlpm.n-_xlpm.k+1)/3)))))) -> 0 | K6: =IF($I6=0,0,IF(OR(K$140=0,K$1<$G6,K$1>$H6+6),0,_xlfn.LET(_xlpm.k,COUNTIFS($J$1:K$1,">="&$G6,$J$140:K$140,">0"),_xlpm.n,$I6,K$140*IF($C6="Bell",EXP(-0.5*((_xlpm.k-(_xlpm.n+1)/2)/MAX(_xlpm.n/6,0.5))^2),IF(_xlpm.n<=6,1,MIN(1,_xlpm.k/3,(_xlpm.n-_xlpm.k+1)/3)))))) -> 0 | L6: =IF($I6=0,0,IF(OR(L$140=0,L$1<$G6,L$1>$H6+6),0,_xlfn.LET(_xlpm.k,COUNTIFS($J$1:L$1,">="&$G6,$J$140:L$140,">0"),_xlpm.n,$I6,L$140*IF($C6="Bell",EXP(-0.5*((_xlpm.k-(_xlpm.n+1)/2)/MAX(_xlpm.n/6,0.5))^2),IF(_xlpm.n<=6,1,MIN(1,_xlpm.k/3,(_xlpm.n-_xlpm.k+1)/3)))))) -> 0 | M6: =IF($I6=0,0,IF(OR(M$140=0,M$1<$G6,M$1>$H6+6),0,_xlfn.LET(_xlpm.k,COUNTIFS($J$1:M$1,">="&$G6,$J$140:M$140,">0"),_xlpm.n,$I6,M$140*IF($C6="Bell",EXP(-0.5*((_xlpm.k-(_xlpm.n+1)/2)/MAX(_xlpm.n/6,0.5))^2),IF(_xlpm.n<=6,1,MIN(1,_xlpm.k/3,(_xlpm.n-_xlpm.k+1)/3)))))) -> 0 | N6: =IF($I6=0,0,IF(OR(N$140=0,N$1<$G6,N$1>$H6+6),0,_xlfn.LET(_xlpm.k,COUNTIFS($J$1:N$1,">="&$G6,$J$140:N$140,">0"),_xlpm.n,$I6,N$140*IF($C6="Bell",EXP(-0.5*((_xlpm.k-(_xlpm.n+1)/2)/MAX(_xlpm.n/6,0.5))^2),IF(_xlpm.n<=6,1,MIN(1,_xlpm.k/3,(_xlpm.n-_xlpm.k+1)/3)))))) -> 0 | O6: =IF($I6=0,0,IF(OR(O$140=0,O$1<$G6,O$1>$H6+6),0,_xlfn.LET(_xlpm.k,COUNTIFS($J$1:O$1,">="&$G6,$J$140:O$140,">0"),_xlpm.n,$I6,O$140*IF($C6="Bell",EXP(-0.5*((_xlpm.k-(_xlpm.n+1)/2)/MAX(_xlpm.n/6,0.5))^2),IF(_xlpm.n<=6,1,MIN(1,_xlpm.k/3,(_xlpm.n-_xlpm.k+1)/3)))))) -> 0 | P6: =IF($I6=0,0,IF(OR(P$140=0,P$1<$G6,P$1>$H6+6),0,_xlfn.LET(_xlpm.k,COUNTIFS($J$1:P$1,">="&$G6,$J$140:P$140,">0"),_xlpm.n,$I6,P$140*IF($C6="Bell",EXP(-0.5*((_xlpm.k-(_xlpm.n+1)/2)/MAX(_xlpm.n/6,0.5))^2),IF(_xlpm.n<=6,1,MIN(1,_xlpm.k/3,(_xlpm.n-_xlpm.k+1)/3)))))) -> 0 | Q6: =IF($I6=0,0,IF(OR(Q$140=0,Q$1<$G6,Q$1>$H6+6),0,_xlfn.LET(_xlpm.k,COUNTIFS($J$1:Q$1,">="&$G6,$J$140:Q$140,">0"),_xlpm.n,$I6,Q$140*IF($C6="Bell",EXP(-0.5*((_xlpm.k-(_xlpm.n+1)/2)/MAX(_xlpm.n/6,0.5))^2),IF(_xlpm.n<=6,1,MIN(1,_xlpm.k/3,(_xlpm.n-_xlpm.k+1)/3)))))) -> 0 | ... GL6: =IF($I6=0,0,IF(OR(GL$140=0,GL$1<$G6,GL$1>$H6+6),0,_xlfn.LET(_xlpm.k,COUNTIFS($J$1:GL$1,">="&$G6,$J$140:GL$140,">0"),_xlpm.n,$I6,GL$140*IF($C6="Bell",EXP(-0.5*((_xlpm.k-(_xlpm.n+1)/2)/MAX(_xlpm.n/6,0.5))^2),IF(_xlpm.n<=6,1,MIN(1,_xlpm.k/3,(_xlpm.n-_xlpm.k+1)/3)))))) -> 0
A7: =Sheet1!B7 -> 0-4004-05 | B7: =Sheet1!D7 -> 0 | E7: =SUM(J7:GL7) -> 0 | G7: =IF(Sheet1!G7="","",Sheet1!G7) | H7: =IF(Sheet1!H7="","",Sheet1!H7) | I7: =IF(OR(G7="",H7=""),0,COUNTIFS($J$1:$GL$1,">="&G7,$J$1:$GL$1,"<="&H7+6,$J$140:$GL$140,">0")) -> 0 | J7: =IF($I7=0,0,IF(OR(J$140=0,J$1<$G7,J$1>$H7+6),0,_xlfn.LET(_xlpm.k,COUNTIFS($J$1:J$1,">="&$G7,$J$140:J$140,">0"),_xlpm.n,$I7,J$140*IF($C7="Bell",EXP(-0.5*((_xlpm.k-(_xlpm.n+1)/2)/MAX(_xlpm.n/6,0.5))^2),IF(_xlpm.n<=6,1,MIN(1,_xlpm.k/3,(_xlpm.n-_xlpm.k+1)/3)))))) -> 0 | K7: =IF($I7=0,0,IF(OR(K$140=0,K$1<$G7,K$1>$H7+6),0,_xlfn.LET(_xlpm.k,COUNTIFS($J$1:K$1,">="&$G7,$J$140:K$140,">0"),_xlpm.n,$I7,K$140*IF($C7="Bell",EXP(-0.5*((_xlpm.k-(_xlpm.n+1)/2)/MAX(_xlpm.n/6,0.5))^2),IF(_xlpm.n<=6,1,MIN(1,_xlpm.k/3,(_xlpm.n-_xlpm.k+1)/3)))))) -> 0 | L7: =IF($I7=0,0,IF(OR(L$140=0,L$1<$G7,L$1>$H7+6),0,_xlfn.LET(_xlpm.k,COUNTIFS($J$1:L$1,">="&$G7,$J$140:L$140,">0"),_xlpm.n,$I7,L$140*IF($C7="Bell",EXP(-0.5*((_xlpm.k-(_xlpm.n+1)/2)/MAX(_xlpm.n/6,0.5))^2),IF(_xlpm.n<=6,1,MIN(1,_xlpm.k/3,(_xlpm.n-_xlpm.k+1)/3)))))) -> 0 | M7: =IF($I7=0,0,IF(OR(M$140=0,M$1<$G7,M$1>$H7+6),0,_xlfn.LET(_xlpm.k,COUNTIFS($J$1:M$1,">="&$G7,$J$140:M$140,">0"),_xlpm.n,$I7,M$140*IF($C7="Bell",EXP(-0.5*((_xlpm.k-(_xlpm.n+1)/2)/MAX(_xlpm.n/6,0.5))^2),IF(_xlpm.n<=6,1,MIN(1,_xlpm.k/3,(_xlpm.n-_xlpm.k+1)/3)))))) -> 0 | N7: =IF($I7=0,0,IF(OR(N$140=0,N$1<$G7,N$1>$H7+6),0,_xlfn.LET(_xlpm.k,COUNTIFS($J$1:N$1,">="&$G7,$J$140:N$140,">0"),_xlpm.n,$I7,N$140*IF($C7="Bell",EXP(-0.5*((_xlpm.k-(_xlpm.n+1)/2)/MAX(_xlpm.n/6,0.5))^2),IF(_xlpm.n<=6,1,MIN(1,_xlpm.k/3,(_xlpm.n-_xlpm.k+1)/3)))))) -> 0 | O7: =IF($I7=0,0,IF(OR(O$140=0,O$1<$G7,O$1>$H7+6),0,_xlfn.LET(_xlpm.k,COUNTIFS($J$1:O$1,">="&$G7,$J$140:O$140,">0"),_xlpm.n,$I7,O$140*IF($C7="Bell",EXP(-0.5*((_xlpm.k-(_xlpm.n+1)/2)/MAX(_xlpm.n/6,0.5))^2),IF(_xlpm.n<=6,1,MIN(1,_xlpm.k/3,(_xlpm.n-_xlpm.k+1)/3)))))) -> 0 | P7: =IF($I7=0,0,IF(OR(P$140=0,P$1<$G7,P$1>$H7+6),0,_xlfn.LET(_xlpm.k,COUNTIFS($J$1:P$1,">="&$G7,$J$140:P$140,">0"),_xlpm.n,$I7,P$140*IF($C7="Bell",EXP(-0.5*((_xlpm.k-(_xlpm.n+1)/2)/MAX(_xlpm.n/6,0.5))^2),IF(_xlpm.n<=6,1,MIN(1,_xlpm.k/3,(_xlpm.n-_xlpm.k+1)/3)))))) -> 0 | Q7: =IF($I7=0,0,IF(OR(Q$140=0,Q$1<$G7,Q$1>$H7+6),0,_xlfn.LET(_xlpm.k,COUNTIFS($J$1:Q$1,">="&$G7,$J$140:Q$140,">0"),_xlpm.n,$I7,Q$140*IF($C7="Bell",EXP(-0.5*((_xlpm.k-(_xlpm.n+1)/2)/MAX(_xlpm.n/6,0.5))^2),IF(_xlpm.n<=6,1,MIN(1,_xlpm.k/3,(_xlpm.n-_xlpm.k+1)/3)))))) -> 0 | ... GL7: =IF($I7=0,0,IF(OR(GL$140=0,GL$1<$G7,GL$1>$H7+6),0,_xlfn.LET(_xlpm.k,COUNTIFS($J$1:GL$1,">="&$G7,$J$140:GL$140,">0"),_xlpm.n,$I7,GL$140*IF($C7="Bell",EXP(-0.5*((_xlpm.k-(_xlpm.n+1)/2)/MAX(_xlpm.n/6,0.5))^2),IF(_xlpm.n<=6,1,MIN(1,_xlpm.k/3,(_xlpm.n-_xlpm.k+1)/3)))))) -> 0
A8: =Sheet1!B8 -> 0-4004-06 | B8: =Sheet1!D8 -> 0 | E8: =SUM(J8:GL8) -> 0 | G8: =IF(Sheet1!G8="","",Sheet1!G8) | H8: =IF(Sheet1!H8="","",Sheet1!H8) | I8: =IF(OR(G8="",H8=""),0,COUNTIFS($J$1:$GL$1,">="&G8,$J$1:$GL$1,"<="&H8+6,$J$140:$GL$140,">0")) -> 0 | J8: =IF($I8=0,0,IF(OR(J$140=0,J$1<$G8,J$1>$H8+6),0,_xlfn.LET(_xlpm.k,COUNTIFS($J$1:J$1,">="&$G8,$J$140:J$140,">0"),_xlpm.n,$I8,J$140*IF($C8="Bell",EXP(-0.5*((_xlpm.k-(_xlpm.n+1)/2)/MAX(_xlpm.n/6,0.5))^2),IF(_xlpm.n<=6,1,MIN(1,_xlpm.k/3,(_xlpm.n-_xlpm.k+1)/3)))))) -> 0 | K8: =IF($I8=0,0,IF(OR(K$140=0,K$1<$G8,K$1>$H8+6),0,_xlfn.LET(_xlpm.k,COUNTIFS($J$1:K$1,">="&$G8,$J$140:K$140,">0"),_xlpm.n,$I8,K$140*IF($C8="Bell",EXP(-0.5*((_xlpm.k-(_xlpm.n+1)/2)/MAX(_xlpm.n/6,0.5))^2),IF(_xlpm.n<=6,1,MIN(1,_xlpm.k/3,(_xlpm.n-_xlpm.k+1)/3)))))) -> 0 | L8: =IF($I8=0,0,IF(OR(L$140=0,L$1<$G8,L$1>$H8+6),0,_xlfn.LET(_xlpm.k,COUNTIFS($J$1:L$1,">="&$G8,$J$140:L$140,">0"),_xlpm.n,$I8,L$140*IF($C8="Bell",EXP(-0.5*((_xlpm.k-(_xlpm.n+1)/2)/MAX(_xlpm.n/6,0.5))^2),IF(_xlpm.n<=6,1,MIN(1,_xlpm.k/3,(_xlpm.n-_xlpm.k+1)/3)))))) -> 0 | M8: =IF($I8=0,0,IF(OR(M$140=0,M$1<$G8,M$1>$H8+6),0,_xlfn.LET(_xlpm.k,COUNTIFS($J$1:M$1,">="&$G8,$J$140:M$140,">0"),_xlpm.n,$I8,M$140*IF($C8="Bell",EXP(-0.5*((_xlpm.k-(_xlpm.n+1)/2)/MAX(_xlpm.n/6,0.5))^2),IF(_xlpm.n<=6,1,MIN(1,_xlpm.k/3,(_xlpm.n-_xlpm.k+1)/3)))))) -> 0 | N8: =IF($I8=0,0,IF(OR(N$140=0,N$1<$G8,N$1>$H8+6),0,_xlfn.LET(_xlpm.k,COUNTIFS($J$1:N$1,">="&$G8,$J$140:N$140,">0"),_xlpm.n,$I8,N$140*IF($C8="Bell",EXP(-0.5*((_xlpm.k-(_xlpm.n+1)/2)/MAX(_xlpm.n/6,0.5))^2),IF(_xlpm.n<=6,1,MIN(1,_xlpm.k/3,(_xlpm.n-_xlpm.k+1)/3)))))) -> 0 | O8: =IF($I8=0,0,IF(OR(O$140=0,O$1<$G8,O$1>$H8+6),0,_xlfn.LET(_xlpm.k,COUNTIFS($J$1:O$1,">="&$G8,$J$140:O$140,">0"),_xlpm.n,$I8,O$140*IF($C8="Bell",EXP(-0.5*((_xlpm.k-(_xlpm.n+1)/2)/MAX(_xlpm.n/6,0.5))^2),IF(_xlpm.n<=6,1,MIN(1,_xlpm.k/3,(_xlpm.n-_xlpm.k+1)/3)))))) -> 0 | P8: =IF($I8=0,0,IF(OR(P$140=0,P$1<$G8,P$1>$H8+6),0,_xlfn.LET(_xlpm.k,COUNTIFS($J$1:P$1,">="&$G8,$J$140:P$140,">0"),_xlpm.n,$I8,P$140*IF($C8="Bell",EXP(-0.5*((_xlpm.k-(_xlpm.n+1)/2)/MAX(_xlpm.n/6,0.5))^2),IF(_xlpm.n<=6,1,MIN(1,_xlpm.k/3,(_xlpm.n-_xlpm.k+1)/3)))))) -> 0 | Q8: =IF($I8=0,0,IF(OR(Q$140=0,Q$1<$G8,Q$1>$H8+6),0,_xlfn.LET(_xlpm.k,COUNTIFS($J$1:Q$1,">="&$G8,$J$140:Q$140,">0"),_xlpm.n,$I8,Q$140*IF($C8="Bell",EXP(-0.5*((_xlpm.k-(_xlpm.n+1)/2)/MAX(_xlpm.n/6,0.5))^2),IF(_xlpm.n<=6,1,MIN(1,_xlpm.k/3,(_xlpm.n-_xlpm.k+1)/3)))))) -> 0 | ... GL8: =IF($I8=0,0,IF(OR(GL$140=0,GL$1<$G8,GL$1>$H8+6),0,_xlfn.LET(_xlpm.k,COUNTIFS($J$1:GL$1,">="&$G8,$J$140:GL$140,">0"),_xlpm.n,$I8,GL$140*IF($C8="Bell",EXP(-0.5*((_xlpm.k-(_xlpm.n+1)/2)/MAX(_xlpm.n/6,0.5))^2),IF(_xlpm.n<=6,1,MIN(1,_xlpm.k/3,(_xlpm.n-_xlpm.k+1)/3)))))) -> 0
A9: =Sheet1!B9 -> 0-4004-07 | B9: =Sheet1!D9 -> 0 | E9: =SUM(J9:GL9) -> 0 | G9: =IF(Sheet1!G9="","",Sheet1!G9) | H9: =IF(Sheet1!H9="","",Sheet1!H9) | I9: =IF(OR(G9="",H9=""),0,COUNTIFS($J$1:$GL$1,">="&G9,$J$1:$GL$1,"<="&H9+6,$J$140:$GL$140,">0")) -> 0 | J9: =IF($I9=0,0,IF(OR(J$140=0,J$1<$G9,J$1>$H9+6),0,_xlfn.LET(_xlpm.k,COUNTIFS($J$1:J$1,">="&$G9,$J$140:J$140,">0"),_xlpm.n,$I9,J$140*IF($C9="Bell",EXP(-0.5*((_xlpm.k-(_xlpm.n+1)/2)/MAX(_xlpm.n/6,0.5))^2),IF(_xlpm.n<=6,1,MIN(1,_xlpm.k/3,(_xlpm.n-_xlpm.k+1)/3)))))) -> 0 | K9: =IF($I9=0,0,IF(OR(K$140=0,K$1<$G9,K$1>$H9+6),0,_xlfn.LET(_xlpm.k,COUNTIFS($J$1:K$1,">="&$G9,$J$140:K$140,">0"),_xlpm.n,$I9,K$140*IF($C9="Bell",EXP(-0.5*((_xlpm.k-(_xlpm.n+1)/2)/MAX(_xlpm.n/6,0.5))^2),IF(_xlpm.n<=6,1,MIN(1,_xlpm.k/3,(_xlpm.n-_xlpm.k+1)/3)))))) -> 0 | L9: =IF($I9=0,0,IF(OR(L$140=0,L$1<$G9,L$1>$H9+6),0,_xlfn.LET(_xlpm.k,COUNTIFS($J$1:L$1,">="&$G9,$J$140:L$140,">0"),_xlpm.n,$I9,L$140*IF($C9="Bell",EXP(-0.5*((_xlpm.k-(_xlpm.n+1)/2)/MAX(_xlpm.n/6,0.5))^2),IF(_xlpm.n<=6,1,MIN(1,_xlpm.k/3,(_xlpm.n-_xlpm.k+1)/3)))))) -> 0 | M9: =IF($I9=0,0,IF(OR(M$140=0,M$1<$G9,M$1>$H9+6),0,_xlfn.LET(_xlpm.k,COUNTIFS($J$1:M$1,">="&$G9,$J$140:M$140,">0"),_xlpm.n,$I9,M$140*IF($C9="Bell",EXP(-0.5*((_xlpm.k-(_xlpm.n+1)/2)/MAX(_xlpm.n/6,0.5))^2),IF(_xlpm.n<=6,1,MIN(1,_xlpm.k/3,(_xlpm.n-_xlpm.k+1)/3)))))) -> 0 | N9: =IF($I9=0,0,IF(OR(N$140=0,N$1<$G9,N$1>$H9+6),0,_xlfn.LET(_xlpm.k,COUNTIFS($J$1:N$1,">="&$G9,$J$140:N$140,">0"),_xlpm.n,$I9,N$140*IF($C9="Bell",EXP(-0.5*((_xlpm.k-(_xlpm.n+1)/2)/MAX(_xlpm.n/6,0.5))^2),IF(_xlpm.n<=6,1,MIN(1,_xlpm.k/3,(_xlpm.n-_xlpm.k+1)/3)))))) -> 0 | O9: =IF($I9=0,0,IF(OR(O$140=0,O$1<$G9,O$1>$H9+6),0,_xlfn.LET(_xlpm.k,COUNTIFS($J$1:O$1,">="&$G9,$J$140:O$140,">0"),_xlpm.n,$I9,O$140*IF($C9="Bell",EXP(-0.5*((_xlpm.k-(_xlpm.n+1)/2)/MAX(_xlpm.n/6,0.5))^2),IF(_xlpm.n<=6,1,MIN(1,_xlpm.k/3,(_xlpm.n-_xlpm.k+1)/3)))))) -> 0 | P9: =IF($I9=0,0,IF(OR(P$140=0,P$1<$G9,P$1>$H9+6),0,_xlfn.LET(_xlpm.k,COUNTIFS($J$1:P$1,">="&$G9,$J$140:P$140,">0"),_xlpm.n,$I9,P$140*IF($C9="Bell",EXP(-0.5*((_xlpm.k-(_xlpm.n+1)/2)/MAX(_xlpm.n/6,0.5))^2),IF(_xlpm.n<=6,1,MIN(1,_xlpm.k/3,(_xlpm.n-_xlpm.k+1)/3)))))) -> 0 | Q9: =IF($I9=0,0,IF(OR(Q$140=0,Q$1<$G9,Q$1>$H9+6),0,_xlfn.LET(_xlpm.k,COUNTIFS($J$1:Q$1,">="&$G9,$J$140:Q$140,">0"),_xlpm.n,$I9,Q$140*IF($C9="Bell",EXP(-0.5*((_xlpm.k-(_xlpm.n+1)/2)/MAX(_xlpm.n/6,0.5))^2),IF(_xlpm.n<=6,1,MIN(1,_xlpm.k/3,(_xlpm.n-_xlpm.k+1)/3)))))) -> 0 | ... GL9: =IF($I9=0,0,IF(OR(GL$140=0,GL$1<$G9,GL$1>$H9+6),0,_xlfn.LET(_xlpm.k,COUNTIFS($J$1:GL$1,">="&$G9,$J$140:GL$140,">0"),_xlpm.n,$I9,GL$140*IF($C9="Bell",EXP(-0.5*((_xlpm.k-(_xlpm.n+1)/2)/MAX(_xlpm.n/6,0.5))^2),IF(_xlpm.n<=6,1,MIN(1,_xlpm.k/3,(_xlpm.n-_xlpm.k+1)/3)))))) -> 0
A10: =Sheet1!B10 -> 0-4004-08 | B10: =Sheet1!D10 -> 0 | E10: =SUM(J10:GL10) -> 0 | G10: =IF(Sheet1!G10="","",Sheet1!G10) | H10: =IF(Sheet1!H10="","",Sheet1!H10) | I10: =IF(OR(G10="",H10=""),0,COUNTIFS($J$1:$GL$1,">="&G10,$J$1:$GL$1,"<="&H10+6,$J$140:$GL$140,">0")) -> 0 | J10: =IF($I10=0,0,IF(OR(J$140=0,J$1<$G10,J$1>$H10+6),0,_xlfn.LET(_xlpm.k,COUNTIFS($J$1:J$1,">="&$G10,$J$140:J$140,">0"),_xlpm.n,$I10,J$140*IF($C10="Bell",EXP(-0.5*((_xlpm.k-(_xlpm.n+1)/2)/MAX(_xlpm.n/6,0.5))^2),IF(_xlpm.n<=6,1,MIN(1,_xlpm.k/3,(_xlpm.n-_xlpm.k+1)/3)))))) -> 0 | K10: =IF($I10=0,0,IF(OR(K$140=0,K$1<$G10,K$1>$H10+6),0,_xlfn.LET(_xlpm.k,COUNTIFS($J$1:K$1,">="&$G10,$J$140:K$140,">0"),_xlpm.n,$I10,K$140*IF($C10="Bell",EXP(-0.5*((_xlpm.k-(_xlpm.n+1)/2)/MAX(_xlpm.n/6,0.5))^2),IF(_xlpm.n<=6,1,MIN(1,_xlpm.k/3,(_xlpm.n-_xlpm.k+1)/3)))))) -> 0 | L10: =IF($I10=0,0,IF(OR(L$140=0,L$1<$G10,L$1>$H10+6),0,_xlfn.LET(_xlpm.k,COUNTIFS($J$1:L$1,">="&$G10,$J$140:L$140,">0"),_xlpm.n,$I10,L$140*IF($C10="Bell",EXP(-0.5*((_xlpm.k-(_xlpm.n+1)/2)/MAX(_xlpm.n/6,0.5))^2),IF(_xlpm.n<=6,1,MIN(1,_xlpm.k/3,(_xlpm.n-_xlpm.k+1)/3)))))) -> 0 | M10: =IF($I10=0,0,IF(OR(M$140=0,M$1<$G10,M$1>$H10+6),0,_xlfn.LET(_xlpm.k,COUNTIFS($J$1:M$1,">="&$G10,$J$140:M$140,">0"),_xlpm.n,$I10,M$140*IF($C10="Bell",EXP(-0.5*((_xlpm.k-(_xlpm.n+1)/2)/MAX(_xlpm.n/6,0.5))^2),IF(_xlpm.n<=6,1,MIN(1,_xlpm.k/3,(_xlpm.n-_xlpm.k+1)/3)))))) -> 0 | N10: =IF($I10=0,0,IF(OR(N$140=0,N$1<$G10,N$1>$H10+6),0,_xlfn.LET(_xlpm.k,COUNTIFS($J$1:N$1,">="&$G10,$J$140:N$140,">0"),_xlpm.n,$I10,N$140*IF($C10="Bell",EXP(-0.5*((_xlpm.k-(_xlpm.n+1)/2)/MAX(_xlpm.n/6,0.5))^2),IF(_xlpm.n<=6,1,MIN(1,_xlpm.k/3,(_xlpm.n-_xlpm.k+1)/3)))))) -> 0 | O10: =IF($I10=0,0,IF(OR(O$140=0,O$1<$G10,O$1>$H10+6),0,_xlfn.LET(_xlpm.k,COUNTIFS($J$1:O$1,">="&$G10,$J$140:O$140,">0"),_xlpm.n,$I10,O$140*IF($C10="Bell",EXP(-0.5*((_xlpm.k-(_xlpm.n+1)/2)/MAX(_xlpm.n/6,0.5))^2),IF(_xlpm.n<=6,1,MIN(1,_xlpm.k/3,(_xlpm.n-_xlpm.k+1)/3)))))) -> 0 | P10: =IF($I10=0,0,IF(OR(P$140=0,P$1<$G10,P$1>$H10+6),0,_xlfn.LET(_xlpm.k,COUNTIFS($J$1:P$1,">="&$G10,$J$140:P$140,">0"),_xlpm.n,$I10,P$140*IF($C10="Bell",EXP(-0.5*((_xlpm.k-(_xlpm.n+1)/2)/MAX(_xlpm.n/6,0.5))^2),IF(_xlpm.n<=6,1,MIN(1,_xlpm.k/3,(_xlpm.n-_xlpm.k+1)/3)))))) -> 0 | Q10: =IF($I10=0,0,IF(OR(Q$140=0,Q$1<$G10,Q$1>$H10+6),0,_xlfn.LET(_xlpm.k,COUNTIFS($J$1:Q$1,">="&$G10,$J$140:Q$140,">0"),_xlpm.n,$I10,Q$140*IF($C10="Bell",EXP(-0.5*((_xlpm.k-(_xlpm.n+1)/2)/MAX(_xlpm.n/6,0.5))^2),IF(_xlpm.n<=6,1,MIN(1,_xlpm.k/3,(_xlpm.n-_xlpm.k+1)/3)))))) -> 0 | ... GL10: =IF($I10=0,0,IF(OR(GL$140=0,GL$1<$G10,GL$1>$H10+6),0,_xlfn.LET(_xlpm.k,COUNTIFS($J$1:GL$1,">="&$G10,$J$140:GL$140,">0"),_xlpm.n,$I10,GL$140*IF($C10="Bell",EXP(-0.5*((_xlpm.k-(_xlpm.n+1)/2)/MAX(_xlpm.n/6,0.5))^2),IF(_xlpm.n<=6,1,MIN(1,_xlpm.k/3,(_xlpm.n-_xlpm.k+1)/3)))))) -> 0
A11: =Sheet1!B11 -> 0-4004-10 | B11: =Sheet1!D11 -> 0 | E11: =SUM(J11:GL11) -> 0 | G11: =IF(Sheet1!G11="","",Sheet1!G11) | H11: =IF(Sheet1!H11="","",Sheet1!H11) | I11: =IF(OR(G11="",H11=""),0,COUNTIFS($J$1:$GL$1,">="&G11,$J$1:$GL$1,"<="&H11+6,$J$140:$GL$140,">0")) -> 0 | J11: =IF($I11=0,0,IF(OR(J$140=0,J$1<$G11,J$1>$H11+6),0,_xlfn.LET(_xlpm.k,COUNTIFS($J$1:J$1,">="&$G11,$J$140:J$140,">0"),_xlpm.n,$I11,J$140*IF($C11="Bell",EXP(-0.5*((_xlpm.k-(_xlpm.n+1)/2)/MAX(_xlpm.n/6,0.5))^2),IF(_xlpm.n<=6,1,MIN(1,_xlpm.k/3,(_xlpm.n-_xlpm.k+1)/3)))))) -> 0 | K11: =IF($I11=0,0,IF(OR(K$140=0,K$1<$G11,K$1>$H11+6),0,_xlfn.LET(_xlpm.k,COUNTIFS($J$1:K$1,">="&$G11,$J$140:K$140,">0"),_xlpm.n,$I11,K$140*IF($C11="Bell",EXP(-0.5*((_xlpm.k-(_xlpm.n+1)/2)/MAX(_xlpm.n/6,0.5))^2),IF(_xlpm.n<=6,1,MIN(1,_xlpm.k/3,(_xlpm.n-_xlpm.k+1)/3)))))) -> 0 | L11: =IF($I11=0,0,IF(OR(L$140=0,L$1<$G11,L$1>$H11+6),0,_xlfn.LET(_xlpm.k,COUNTIFS($J$1:L$1,">="&$G11,$J$140:L$140,">0"),_xlpm.n,$I11,L$140*IF($C11="Bell",EXP(-0.5*((_xlpm.k-(_xlpm.n+1)/2)/MAX(_xlpm.n/6,0.5))^2),IF(_xlpm.n<=6,1,MIN(1,_xlpm.k/3,(_xlpm.n-_xlpm.k+1)/3)))))) -> 0 | M11: =IF($I11=0,0,IF(OR(M$140=0,M$1<$G11,M$1>$H11+6),0,_xlfn.LET(_xlpm.k,COUNTIFS($J$1:M$1,">="&$G11,$J$140:M$140,">0"),_xlpm.n,$I11,M$140*IF($C11="Bell",EXP(-0.5*((_xlpm.k-(_xlpm.n+1)/2)/MAX(_xlpm.n/6,0.5))^2),IF(_xlpm.n<=6,1,MIN(1,_xlpm.k/3,(_xlpm.n-_xlpm.k+1)/3)))))) -> 0 | N11: =IF($I11=0,0,IF(OR(N$140=0,N$1<$G11,N$1>$H11+6),0,_xlfn.LET(_xlpm.k,COUNTIFS($J$1:N$1,">="&$G11,$J$140:N$140,">0"),_xlpm.n,$I11,N$140*IF($C11="Bell",EXP(-0.5*((_xlpm.k-(_xlpm.n+1)/2)/MAX(_xlpm.n/6,0.5))^2),IF(_xlpm.n<=6,1,MIN(1,_xlpm.k/3,(_xlpm.n-_xlpm.k+1)/3)))))) -> 0 | O11: =IF($I11=0,0,IF(OR(O$140=0,O$1<$G11,O$1>$H11+6),0,_xlfn.LET(_xlpm.k,COUNTIFS($J$1:O$1,">="&$G11,$J$140:O$140,">0"),_xlpm.n,$I11,O$140*IF($C11="Bell",EXP(-0.5*((_xlpm.k-(_xlpm.n+1)/2)/MAX(_xlpm.n/6,0.5))^2),IF(_xlpm.n<=6,1,MIN(1,_xlpm.k/3,(_xlpm.n-_xlpm.k+1)/3)))))) -> 0 | P11: =IF($I11=0,0,IF(OR(P$140=0,P$1<$G11,P$1>$H11+6),0,_xlfn.LET(_xlpm.k,COUNTIFS($J$1:P$1,">="&$G11,$J$140:P$140,">0"),_xlpm.n,$I11,P$140*IF($C11="Bell",EXP(-0.5*((_xlpm.k-(_xlpm.n+1)/2)/MAX(_xlpm.n/6,0.5))^2),IF(_xlpm.n<=6,1,MIN(1,_xlpm.k/3,(_xlpm.n-_xlpm.k+1)/3)))))) -> 0 | Q11: =IF($I11=0,0,IF(OR(Q$140=0,Q$1<$G11,Q$1>$H11+6),0,_xlfn.LET(_xlpm.k,COUNTIFS($J$1:Q$1,">="&$G11,$J$140:Q$140,">0"),_xlpm.n,$I11,Q$140*IF($C11="Bell",EXP(-0.5*((_xlpm.k-(_xlpm.n+1)/2)/MAX(_xlpm.n/6,0.5))^2),IF(_xlpm.n<=6,1,MIN(1,_xlpm.k/3,(_xlpm.n-_xlpm.k+1)/3)))))) -> 0 | ... GL11: =IF($I11=0,0,IF(OR(GL$140=0,GL$1<$G11,GL$1>$H11+6),0,_xlfn.LET(_xlpm.k,COUNTIFS($J$1:GL$1,">="&$G11,$J$140:GL$140,">0"),_xlpm.n,$I11,GL$140*IF($C11="Bell",EXP(-0.5*((_xlpm.k-(_xlpm.n+1)/2)/MAX(_xlpm.n/6,0.5))^2),IF(_xlpm.n<=6,1,MIN(1,_xlpm.k/3,(_xlpm.n-_xlpm.k+1)/3)))))) -> 0
